Workbook
Name a: #REF!
Name aa: #REF!
Name b: #REF!
Name bbb: #REF!
Name ki: [1]电器仓!#REF!
Name t_Schema: #REF!
Name uti: #REF!
Name 百货收入成本表: #REF!
Name 成本: #REF!
Name 成本倒算: #REF!
Name 橱柜: [2]电器仓!#REF!
Name 戴奥: #REF!
Name 倒算: [3]电器仓!#REF!
Name 诶哟: [4]电器仓!#REF!
Name 儿童: #REF!
Name 费用警示: [5]汇总表!$U$6:$U$9
Name 核算项目___供应商_A___供应商: #REF!
Name 核算项目分类总账: #REF!
Name 核算项目分类总账: #REF!
Name 核算项目分类总账: #REF!
Name 核算项目分类总账: #REF!
Name 核算项目分类总账: #REF!
Name 核算项目明细账: #REF!
Name 核算项目余额表: #REF!
Name 会计分录序时簿: #REF!
Name 就死: #REF!
Name 科目: #REF!
Name 科目: #REF!
Name 科目: #REF!
Name 科目: #REF!
Name 科目: #REF!
Name 科目余额表: #REF!
Name 客户___E_厨衣工程部_: #REF!
Name 明细: #REF!
Name 明细分类账: #REF!
Name 生产领料序时簿: [6]生产领料序时簿!$A$1:$P$12156
Name 是: [7]电器仓!#REF!
Name 说的: #REF!
Name 卫浴柜身车间: [4]电器仓!#REF!
Name 我的: #REF!
Name 无: [8]电器仓!#REF!
Name 销售出库序时簿: [9]电器仓!#REF!
Name 销售订单序时簿: #REF!
Name 衣柜: [8]电器仓!#REF!
Name 增长类型: '[10]2013年费用明细'!$AA$3:$AA$8
Name 装: #REF!
Name 总表: #REF!
Name 总分类账: #REF!

Sheet 经营明细（集团取数）
A1: 2019年橱柜营销线经营情况明细表 | V1: 返回目录
U2: 单位：万元
A3: 部门 | B3: 项目 | C3: 口径 | D3: 类别 | E3: 本月 | F3: 1月 | G3: 2月 | H3: 3月 | I3: 4月 | J3: 5月 | K3: 6月 | L3: 7月 | M3: 8月 | N3: 9月 | O3: 10月 | P3: 11月 | Q3: 12月 | R3: 本年累计 | S3: 上年同期 | T3: 上年全年 | U3: 增长率
A4: 橱柜经销一部 | B4: 收入 | C4: 按产品 | D4: 柜门 | E4: ='4.经营实际明细S'!E4 -> 3262.746 | F4: ='4.经营实际明细S'!F4 -> 882.7972 | G4: ='4.经营实际明细S'!G4 -> 218.0495 | H4: ='4.经营实际明细S'!H4 -> 1458.3992 | I4: ='4.经营实际明细S'!I4 -> 2038.8118 | J4: ='4.经营实际明细S'!J4 -> 2848.1602 | K4: ='4.经营实际明细S'!K4 -> 3262.746 | L4: ='4.经营实际明细S'!L4 -> 0 | ... Q4: ='4.经营实际明细S'!Q4 -> 0 | R4: =SUM(F4:Q4) -> 10708.964 | S4: =基数汇总!S1204 -> 0 | T4: =基数汇总!R1204 -> 0 | U4: =IF(S4>0,R4/S4-1,"") | V4: =E4=M4 -> FALSE | W4: 收入
D5: 台面 | E5: ='4.经营实际明细S'!E5 -> 1827.0219 | F5: ='4.经营实际明细S'!F5 -> 494.974 | G5: ='4.经营实际明细S'!G5 -> 24.6101 | H5: ='4.经营实际明细S'!H5 -> 947.2568 | I5: ='4.经营实际明细S'!I5 -> 1219.9439 | J5: ='4.经营实际明细S'!J5 -> 1624.3654 | K5: ='4.经营实际明细S'!K5 -> 1827.0219 | L5: ='4.经营实际明细S'!L5 -> 0 | ... Q5: ='4.经营实际明细S'!Q5 -> 0 | R5: =SUM(F5:Q5) -> 6138.1721 | S5: =基数汇总!S1205 -> 0 | T5: =基数汇总!R1205 -> 0 | U5: =IF(S5>0,R5/S5-1,"") | V5: =E5=M5 -> FALSE | W5: 收入
D6: OEM烟灶 | E6: ='4.经营实际明细S'!E6 -> 1065.5691 | F6: ='4.经营实际明细S'!F6 -> 150.52394 | G6: ='4.经营实际明细S'!G6 -> 27.740952 | H6: ='4.经营实际明细S'!H6 -> 517.11127 | I6: ='4.经营实际明细S'!I6 -> 650.52488 | J6: ='4.经营实际明细S'!J6 -> 1301.9301 | K6: ='4.经营实际明细S'!K6 -> 1065.5691 | L6: ='4.经营实际明细S'!L6 -> 0 | ... Q6: ='4.经营实际明细S'!Q6 -> 0 | R6: =SUM(F6:Q6) -> 3713.4002 | S6: =基数汇总!S1206 -> 0 | T6: =基数汇总!R1206 -> 0 | U6: =IF(S6>0,R6/S6-1,"") | V6: =E6=M6 -> FALSE | W6: 收入
D7: OEM其他 | E7: ='4.经营实际明细S'!E7-#REF! -> #REF! | F7: ='4.经营实际明细S'!F7-#REF! -> #REF! | G7: ='4.经营实际明细S'!G7-#REF! -> #REF! | H7: ='4.经营实际明细S'!H7-#REF! -> #REF! | I7: ='4.经营实际明细S'!I7-#REF! -> #REF! | J7: ='4.经营实际明细S'!J7-#REF! -> #REF! | K7: ='4.经营实际明细S'!K7-#REF! -> #REF! | L7: ='4.经营实际明细S'!L7-#REF! -> #REF! | ... T7: ='4.经营实际明细S'!T7-#REF! -> #REF! | U7: =IF(S7>0,R7/S7-1,"") -> #REF! | V7: =E7=M7 -> #REF! | W7: 收入
D8: 自制烟灶 | E8: ='4.经营实际明细S'!E8 -> 496.16044 | F8: ='4.经营实际明细S'!F8 -> 109.2042 | G8: ='4.经营实际明细S'!G8 -> 3.1485 | H8: ='4.经营实际明细S'!H8 -> 243.75079 | I8: ='4.经营实际明细S'!I8 -> 375.42012 | J8: ='4.经营实际明细S'!J8 -> 679.01294 | K8: ='4.经营实际明细S'!K8 -> 496.16044 | L8: ='4.经营实际明细S'!L8 -> 0 | ... Q8: ='4.经营实际明细S'!Q8 -> 0 | R8: =SUM(F8:Q8) -> 1906.697 | S8: =基数汇总!S1208 -> 0 | T8: =基数汇总!R1208 -> 0 | U8: =IF(S8>0,R8/S8-1,"") | V8: =E8=M8 -> FALSE | W8: 收入
D9: 其他加收 | E9: ='4.经营实际明细S'!E11 -> 13.7832 | F9: ='4.经营实际明细S'!F11 -> 1.1902 | G9: ='4.经营实际明细S'!G11 -> 0.18 | H9: ='4.经营实际明细S'!H11 -> 1.2159 | I9: ='4.经营实际明细S'!I11 -> 2.5061 | J9: ='4.经营实际明细S'!J11 -> 3.3347 | K9: ='4.经营实际明细S'!K11 -> 13.7832 | L9: ='4.经营实际明细S'!L11 -> 0 | ... Q9: ='4.经营实际明细S'!Q11 -> 0 | R9: =SUM(F9:Q9) -> 22.2101 | S9: =基数汇总!S1209 -> 0 | T9: =基数汇总!R1209 -> 0 | U9: =IF(S9>0,R9/S9-1,"") | V9: =E9=M9 -> FALSE | W9: 收入
C10: 按订单类型 | D10: 常规单 | E10: ='4.经营实际明细S'!E12-#REF! -> #REF! | F10: ='4.经营实际明细S'!F12-#REF! -> #REF! | G10: ='4.经营实际明细S'!G12-#REF! -> #REF! | H10: ='4.经营实际明细S'!H12-#REF! -> #REF! | I10: ='4.经营实际明细S'!I12-#REF! -> #REF! | J10: ='4.经营实际明细S'!J12-#REF! -> #REF! | K10: ='4.经营实际明细S'!K12-#REF! -> #REF! | L10: ='4.经营实际明细S'!L12-#REF! -> #REF! | ... T10: ='4.经营实际明细S'!T12-#REF! -> #REF! | U10: =IF(S10>0,R10/S10-1,"") -> #REF! | V10: =E10=M10 -> #REF! | W10: 收入
D11: 家装单 | E11: ='4.经营实际明细S'!E13 -> 756.7222 | F11: ='4.经营实际明细S'!F13 -> 142.4542 | G11: ='4.经营实际明细S'!G13 -> 2.6275 | H11: ='4.经营实际明细S'!H13 -> 279.4453 | I11: ='4.经营实际明细S'!I13 -> 417.3637 | J11: ='4.经营实际明细S'!J13 -> 546.0461 | K11: ='4.经营实际明细S'!K13 -> 756.7222 | L11: ='4.经营实际明细S'!L13 -> 0 | ... Q11: ='4.经营实际明细S'!Q13 -> 0 | R11: =SUM(F11:Q11) -> 2144.659 | S11: =基数汇总!S1211 -> 0 | T11: =基数汇总!R1211 -> 0 | U11: =IF(S11>0,R11/S11-1,"") | V11: =E11=M11 -> FALSE | W11: 收入
D12: 直供单 | E12: ='4.经营实际明细S'!E14 -> 1226.1848 | F12: ='4.经营实际明细S'!F14 -> 195.3872 | G12: ='4.经营实际明细S'!G14 -> 10.7569 | H12: ='4.经营实际明细S'!H14 -> 409.9069 | I12: ='4.经营实际明细S'!I14 -> 487.7633 | J12: ='4.经营实际明细S'!J14 -> 933.5302 | K12: ='4.经营实际明细S'!K14 -> 1226.1848 | L12: ='4.经营实际明细S'!L14 -> 0 | ... Q12: ='4.经营实际明细S'!Q14 -> 0 | R12: =SUM(F12:Q12) -> 3263.5293 | S12: =基数汇总!S1212 -> 0 | T12: =基数汇总!R1212 -> 0 | U12: =IF(S12>0,R12/S12-1,"") | V12: =E12=M12 -> FALSE | W12: 收入
D13: 网销单 | E13: ='4.经营实际明细S'!E15 -> 0 | F13: ='4.经营实际明细S'!F15 -> 0 | G13: ='4.经营实际明细S'!G15 -> 0 | H13: ='4.经营实际明细S'!H15 -> 0 | I13: ='4.经营实际明细S'!I15 -> 0 | J13: ='4.经营实际明细S'!J15 -> 0 | K13: ='4.经营实际明细S'!K15 -> 0 | L13: ='4.经营实际明细S'!L15 -> 0 | ... Q13: ='4.经营实际明细S'!Q15 -> 0 | R13: =SUM(F13:Q13) -> 0 | S13: =基数汇总!S1213 -> 0 | T13: =基数汇总!R1213 -> 0 | U13: =IF(S13>0,R13/S13-1,"") | V13: =E13=M13 -> TRUE | W13: 收入
D14: 星居单 | E14: ='4.经营实际明细S'!E16 -> 65.4746 | F14: ='4.经营实际明细S'!F16 -> 11.9667 | G14: ='4.经营实际明细S'!G16 -> 0.0175 | H14: ='4.经营实际明细S'!H16 -> 28.7805 | I14: ='4.经营实际明细S'!I16 -> 43.0319 | J14: ='4.经营实际明细S'!J16 -> 57.0708 | K14: ='4.经营实际明细S'!K16 -> 65.4746 | L14: ='4.经营实际明细S'!L16 -> 0 | ... Q14: ='4.经营实际明细S'!Q16 -> 0 | R14: =SUM(F14:Q14) -> 206.342 | S14: =基数汇总!S1214 -> 0 | T14: =基数汇总!R1214 -> 0 | U14: =IF(S14>0,R14/S14-1,"") | V14: =E14=M14 -> FALSE | W14: 收入
D15: 微居单 | E15: ='4.经营实际明细S'!E17 -> 3.6442 | F15: ='4.经营实际明细S'!F17 -> 6.8726 | G15: ='4.经营实际明细S'!G17 -> 2.5441 | H15: ='4.经营实际明细S'!H17 -> 4.1213 | I15: ='4.经营实际明细S'!I17 -> -0.036 | J15: ='4.经营实际明细S'!J17 -> 5.7267 | K15: ='4.经营实际明细S'!K17 -> 3.6442 | L15: ='4.经营实际明细S'!L17 -> 0 | ... Q15: ='4.经营实际明细S'!Q17 -> 0 | R15: =SUM(F15:Q15) -> 22.8729 | S15: =基数汇总!S1215 -> 0 | T15: =基数汇总!R1215 -> 0 | U15: =IF(S15>0,R15/S15-1,"") | V15: =E15=M15 -> FALSE | W15: 收入
C16: 按合同类型 | D16: 普通单 | E16: ='4.经营实际明细S'!E18-#REF! -> #REF! | F16: ='4.经营实际明细S'!F18-#REF! -> #REF! | G16: ='4.经营实际明细S'!G18-#REF! -> #REF! | H16: ='4.经营实际明细S'!H18-#REF! -> #REF! | I16: ='4.经营实际明细S'!I18-#REF! -> #REF! | J16: ='4.经营实际明细S'!J18-#REF! -> #REF! | K16: ='4.经营实际明细S'!K18-#REF! -> #REF! | L16: ='4.经营实际明细S'!L18-#REF! -> #REF! | ... T16: ='4.经营实际明细S'!T18-#REF! -> #REF! | U16: =IF(S16>0,R16/S16-1,"") -> #REF! | V16: =E16=M16 -> #REF! | W16: 收入
D17: 样品单 | E17: ='4.经营实际明细S'!E19 -> 1169.2153 | F17: ='4.经营实际明细S'!F19 -> 185.22204 | G17: ='4.经营实际明细S'!G19 -> 133.08394 | H17: ='4.经营实际明细S'!H19 -> 1725.8406 | I17: ='4.经营实际明细S'!I19 -> 648.00794 | J17: ='4.经营实际明细S'!J19 -> 1064.5288 | K17: ='4.经营实际明细S'!K19 -> 1169.2153 | L17: ='4.经营实际明细S'!L19 -> 0 | ... Q17: ='4.经营实际明细S'!Q19 -> 0 | R17: =SUM(F17:Q17) -> 4925.8987 | S17: =基数汇总!S1217 -> 0 | T17: =基数汇总!R1217 -> 0 | U17: =IF(S17>0,R17/S17-1,"") | V17: =E17=M17 -> FALSE | W17: 收入
D18: 遗留单 | E18: ='4.经营实际明细S'!E20 -> 58.8518 | F18: ='4.经营实际明细S'!F20 -> 0 | G18: ='4.经营实际明细S'!G20 -> 56.5677 | H18: ='4.经营实际明细S'!H20 -> 38.6051 | I18: ='4.经营实际明细S'!I20 -> 69.7847 | J18: ='4.经营实际明细S'!J20 -> 48.8862 | K18: ='4.经营实际明细S'!K20 -> 58.8518 | L18: ='4.经营实际明细S'!L20 -> 0 | ... Q18: ='4.经营实际明细S'!Q20 -> 0 | R18: =SUM(F18:Q18) -> 272.6955 | S18: =基数汇总!S1218 -> 0 | T18: =基数汇总!R1218 -> 0 | U18: =IF(S18>0,R18/S18-1,"") | V18: =E18=M18 -> FALSE | W18: 收入
B19: 成本 | C19: 按产品 | D19: 柜门 | E19: ='4.经营实际明细S'!E21 -> 2348.8346 | F19: ='4.经营实际明细S'!F21 -> 613.94664 | G19: ='4.经营实际明细S'!G21 -> 197.39169 | H19: ='4.经营实际明细S'!H21 -> 1040.4021 | I19: ='4.经营实际明细S'!I21 -> 1466.1016 | J19: ='4.经营实际明细S'!J21 -> 2036.8079 | K19: ='4.经营实际明细S'!K21 -> 2348.8346 | L19: ='4.经营实际明细S'!L21 -> 0 | ... Q19: ='4.经营实际明细S'!Q21 -> 0 | R19: =SUM(F19:Q19) -> 7703.4845 | S19: =基数汇总!S1219 -> 0 | T19: =基数汇总!R1219 -> 0 | U19: =IF(S19>0,R19/S19-1,"") | V19: =E19=M19 -> FALSE | W19: 成本
D20: 台面 | E20: ='4.经营实际明细S'!E22 -> 1380.4815 | F20: ='4.经营实际明细S'!F22 -> 341.47993 | G20: ='4.经营实际明细S'!G22 -> 20.251868 | H20: ='4.经营实际明细S'!H22 -> 657.64611 | I20: ='4.经营实际明细S'!I22 -> 830.99665 | J20: ='4.经营实际明细S'!J22 -> 1118.9076 | K20: ='4.经营实际明细S'!K22 -> 1380.4815 | L20: ='4.经营实际明细S'!L22 -> 0 | ... Q20: ='4.经营实际明细S'!Q22 -> 0 | R20: =SUM(F20:Q20) -> 4349.7636 | S20: =基数汇总!S1220 -> 0 | T20: =基数汇总!R1220 -> 0 | U20: =IF(S20>0,R20/S20-1,"") | V20: =E20=M20 -> FALSE | W20: 成本
D21: OEM烟灶 | E21: ='4.经营实际明细S'!E23 -> 619.02649 | F21: ='4.经营实际明细S'!F23 -> 90.785403 | G21: ='4.经营实际明细S'!G23 -> 18.001939 | H21: ='4.经营实际明细S'!H23 -> 395.85953 | I21: ='4.经营实际明细S'!I23 -> 414.35336 | J21: ='4.经营实际明细S'!J23 -> 749.7923 | K21: ='4.经营实际明细S'!K23 -> 619.02649 | L21: ='4.经营实际明细S'!L23 -> 0 | ... Q21: ='4.经营实际明细S'!Q23 -> 0 | R21: =SUM(F21:Q21) -> 2287.819 | S21: =基数汇总!S1221 -> 0 | T21: =基数汇总!R1221 -> 0 | U21: =IF(S21>0,R21/S21-1,"") | V21: =E21=M21 -> FALSE | W21: 成本
D22: OEM其他 | E22: ='4.经营实际明细S'!E24-#REF! -> #REF! | F22: ='4.经营实际明细S'!F24-#REF! -> #REF! | G22: ='4.经营实际明细S'!G24-#REF! -> #REF! | H22: ='4.经营实际明细S'!H24-#REF! -> #REF! | I22: ='4.经营实际明细S'!I24-#REF! -> #REF! | J22: ='4.经营实际明细S'!J24-#REF! -> #REF! | K22: ='4.经营实际明细S'!K24-#REF! -> #REF! | L22: ='4.经营实际明细S'!L24-#REF! -> #REF! | ... T22: ='4.经营实际明细S'!T24-#REF! -> #REF! | U22: =IF(S22>0,R22/S22-1,"") -> #REF! | V22: =E22=M22 -> #REF! | W22: 成本
D23: 自制烟灶 | E23: ='4.经营实际明细S'!E25 -> 243.10799 | F23: ='4.经营实际明细S'!F25 -> 58.5815 | G23: ='4.经营实际明细S'!G25 -> 1.5616 | H23: ='4.经营实际明细S'!H25 -> 127.86267 | I23: ='4.经营实际明细S'!I25 -> 190.12967 | J23: ='4.经营实际明细S'!J25 -> 335.96328 | K23: ='4.经营实际明细S'!K25 -> 243.10799 | L23: ='4.经营实际明细S'!L25 -> 0 | ... Q23: ='4.经营实际明细S'!Q25 -> 0 | R23: =SUM(F23:Q23) -> 957.2067 | S23: =基数汇总!S1223 -> 0 | T23: =基数汇总!R1223 -> 0 | U23: =IF(S23>0,R23/S23-1,"") | V23: =E23=M23 -> FALSE | W23: 成本
D24: 其他加收 | E24: ='4.经营实际明细S'!E28 -> 0 | F24: ='4.经营实际明细S'!F28 -> 0 | G24: ='4.经营实际明细S'!G28 -> 0 | H24: ='4.经营实际明细S'!H28 -> 0 | I24: ='4.经营实际明细S'!I28 -> 0 | J24: ='4.经营实际明细S'!J28 -> 0 | K24: ='4.经营实际明细S'!K28 -> 0 | L24: ='4.经营实际明细S'!L28 -> 0 | ... Q24: ='4.经营实际明细S'!Q28 -> 0 | R24: =SUM(F24:Q24) -> 0 | S24: =基数汇总!S1224 -> 0 | T24: =基数汇总!R1224 -> 0 | U24: =IF(S24>0,R24/S24-1,"") | V24: =E24=M24 -> TRUE | W24: 成本
C25: 按订单类型 | D25: 常规单 | E25: ='4.经营实际明细S'!E29-#REF! -> #REF! | F25: ='4.经营实际明细S'!F29-#REF! -> #REF! | G25: ='4.经营实际明细S'!G29-#REF! -> #REF! | H25: ='4.经营实际明细S'!H29-#REF! -> #REF! | I25: ='4.经营实际明细S'!I29-#REF! -> #REF! | J25: ='4.经营实际明细S'!J29-#REF! -> #REF! | K25: ='4.经营实际明细S'!K29-#REF! -> #REF! | L25: ='4.经营实际明细S'!L29-#REF! -> #REF! | ... T25: ='4.经营实际明细S'!T29-#REF! -> #REF! | U25: =IF(S25>0,R25/S25-1,"") -> #REF! | V25: =E25=M25 -> #REF! | W25: 成本
D26: 家装单 | E26: ='4.经营实际明细S'!E30 -> 598.43627 | F26: ='4.经营实际明细S'!F30 -> 99.684994 | G26: ='4.经营实际明细S'!G30 -> 1.7068388 | H26: ='4.经营实际明细S'!H30 -> 200.65863 | I26: ='4.经营实际明细S'!I30 -> 312.59058 | J26: ='4.经营实际明细S'!J30 -> 394.11776 | K26: ='4.经营实际明细S'!K30 -> 598.43627 | L26: ='4.经营实际明细S'!L30 -> 0 | ... Q26: ='4.经营实际明细S'!Q30 -> 0 | R26: =SUM(F26:Q26) -> 1607.1951 | S26: =基数汇总!S1226 -> 0 | T26: =基数汇总!R1226 -> 0 | U26: =IF(S26>0,R26/S26-1,"") | V26: =E26=M26 -> FALSE | W26: 成本
D27: 直供单 | E27: ='4.经营实际明细S'!E31 -> 994.85471 | F27: ='4.经营实际明细S'!F31 -> 130.78289 | G27: ='4.经营实际明细S'!G31 -> 7.8426844 | H27: ='4.经营实际明细S'!H31 -> 278.66127 | I27: ='4.经营实际明细S'!I31 -> 334.75083 | J27: ='4.经营实际明细S'!J31 -> 618.00693 | K27: ='4.经营实际明细S'!K31 -> 994.85471 | L27: ='4.经营实际明细S'!L31 -> 0 | ... Q27: ='4.经营实际明细S'!Q31 -> 0 | R27: =SUM(F27:Q27) -> 2364.8993 | S27: =基数汇总!S1227 -> 0 | T27: =基数汇总!R1227 -> 0 | U27: =IF(S27>0,R27/S27-1,"") | V27: =E27=M27 -> FALSE | W27: 成本
D28: 网销单 | E28: ='4.经营实际明细S'!E32 -> 0 | F28: ='4.经营实际明细S'!F32 -> 0 | G28: ='4.经营实际明细S'!G32 -> 0 | H28: ='4.经营实际明细S'!H32 -> 0 | I28: ='4.经营实际明细S'!I32 -> 0 | J28: ='4.经营实际明细S'!J32 -> 0 | K28: ='4.经营实际明细S'!K32 -> 0 | L28: ='4.经营实际明细S'!L32 -> 0 | ... Q28: ='4.经营实际明细S'!Q32 -> 0 | R28: =SUM(F28:Q28) -> 0 | S28: =基数汇总!S1228 -> 0 | T28: =基数汇总!R1228 -> 0 | U28: =IF(S28>0,R28/S28-1,"") | V28: =E28=M28 -> TRUE | W28: 成本
D29: 星居单 | E29: ='4.经营实际明细S'!E33 -> 45.214408 | F29: ='4.经营实际明细S'!F33 -> 7.9154301 | G29: ='4.经营实际明细S'!G33 -> 0.01292724 | H29: ='4.经营实际明细S'!H33 -> 19.249475 | I29: ='4.经营实际明细S'!I33 -> 29.079337 | J29: ='4.经营实际明细S'!J33 -> 38.93063 | K29: ='4.经营实际明细S'!K33 -> 45.214408 | L29: ='4.经营实际明细S'!L33 -> 0 | ... Q29: ='4.经营实际明细S'!Q33 -> 0 | R29: =SUM(F29:Q29) -> 140.40221 | S29: =基数汇总!S1229 -> 0 | T29: =基数汇总!R1229 -> 0 | U29: =IF(S29>0,R29/S29-1,"") | V29: =E29=M29 -> FALSE | W29: 成本
D30: 微居单 | E30: ='4.经营实际明细S'!E34 -> 2.8126861 | F30: ='4.经营实际明细S'!F34 -> 5.3655678 | G30: ='4.经营实际明细S'!G34 -> 2.0829591 | H30: ='4.经营实际明细S'!H34 -> 3.2597156 | I30: ='4.经营实际明细S'!I34 -> -0.028950529 | J30: ='4.经营实际明细S'!J34 -> 4.6718265 | K30: ='4.经营实际明细S'!K34 -> 2.8126861 | L30: ='4.经营实际明细S'!L34 -> 0 | ... Q30: ='4.经营实际明细S'!Q34 -> 0 | R30: =SUM(F30:Q30) -> 18.163805 | S30: =基数汇总!S1230 -> 0 | T30: =基数汇总!R1230 -> 0 | U30: =IF(S30>0,R30/S30-1,"") | V30: =E30=M30 -> FALSE | W30: 成本
C31: 按合同类型 | D31: 普通单 | E31: ='4.经营实际明细S'!E35-#REF! -> #REF! | F31: ='4.经营实际明细S'!F35-#REF! -> #REF! | G31: ='4.经营实际明细S'!G35-#REF! -> #REF! | H31: ='4.经营实际明细S'!H35-#REF! -> #REF! | I31: ='4.经营实际明细S'!I35-#REF! -> #REF! | J31: ='4.经营实际明细S'!J35-#REF! -> #REF! | K31: ='4.经营实际明细S'!K35-#REF! -> #REF! | L31: ='4.经营实际明细S'!L35-#REF! -> #REF! | ... T31: ='4.经营实际明细S'!T35-#REF! -> #REF! | U31: =IF(S31>0,R31/S31-1,"") -> #REF! | V31: =E31=M31 -> #REF! | W31: 成本
D32: 样品单 | E32: ='4.经营实际明细S'!E36 -> 880.00395 | F32: ='4.经营实际明细S'!F36 -> 144.38394 | G32: ='4.经营实际明细S'!G36 -> 129.55535 | H32: ='4.经营实际明细S'!H36 -> 1203.9785 | I32: ='4.经营实际明细S'!I36 -> 486.52707 | J32: ='4.经营实际明细S'!J36 -> 794.07675 | K32: ='4.经营实际明细S'!K36 -> 880.00395 | L32: ='4.经营实际明细S'!L36 -> 0 | ... Q32: ='4.经营实际明细S'!Q36 -> 0 | R32: =SUM(F32:Q32) -> 3638.5255 | S32: =基数汇总!S1232 -> 0 | T32: =基数汇总!R1232 -> 0 | U32: =IF(S32>0,R32/S32-1,"") | V32: =E32=M32 -> FALSE | W32: 成本
D33: 遗留单 | E33: ='4.经营实际明细S'!E37 -> 45.550782 | F33: ='4.经营实际明细S'!F37 -> 9.182839 | G33: ='4.经营实际明细S'!G37 -> 38.825615 | H33: ='4.经营实际明细S'!H37 -> 30.237687 | I33: ='4.经营实际明细S'!I37 -> 44.508878 | J33: ='4.经营实际明细S'!J37 -> 37.845278 | K33: ='4.经营实际明细S'!K37 -> 45.550782 | L33: ='4.经营实际明细S'!L37 -> 0 | ... Q33: ='4.经营实际明细S'!Q37 -> 0 | R33: =SUM(F33:Q33) -> 206.15108 | S33: =基数汇总!S1233 -> 0 | T33: =基数汇总!R1233 -> 0 | U33: =IF(S33>0,R33/S33-1,"") | V33: =E33=M33 -> FALSE | W33: 成本
B34: 毛利 | C34: 按产品 | D34: 柜门 | E34: ='4.经营实际明细S'!E38 -> 913.91144 | F34: ='4.经营实际明细S'!F38 -> 268.85056 | G34: ='4.经营实际明细S'!G38 -> 20.657814 | H34: ='4.经营实际明细S'!H38 -> 417.9971 | I34: ='4.经营实际明细S'!I38 -> 572.71017 | J34: ='4.经营实际明细S'!J38 -> 811.35228 | K34: ='4.经营实际明细S'!K38 -> 913.91144 | L34: ='4.经营实际明细S'!L38 -> 0 | ... Q34: ='4.经营实际明细S'!Q38 -> 0 | R34: =SUM(F34:Q34) -> 3005.4794 | S34: =基数汇总!S1234 -> 0 | T34: =基数汇总!R1234 -> 0 | U34: =IF(S34>0,R34/S34-1,"") | V34: =E34=M34 -> FALSE | W34: 毛利
D35: 台面 | E35: ='4.经营实际明细S'!E39 -> 446.54042 | F35: ='4.经营实际明细S'!F39 -> 153.49407 | G35: ='4.经营实际明细S'!G39 -> 4.358232 | H35: ='4.经营实际明细S'!H39 -> 289.61069 | I35: ='4.经营实际明细S'!I39 -> 388.94725 | J35: ='4.经营实际明细S'!J39 -> 505.45781 | K35: ='4.经营实际明细S'!K39 -> 446.54042 | L35: ='4.经营实际明细S'!L39 -> 0 | ... Q35: ='4.经营实际明细S'!Q39 -> 0 | R35: =SUM(F35:Q35) -> 1788.4085 | S35: =基数汇总!S1235 -> 0 | T35: =基数汇总!R1235 -> 0 | U35: =IF(S35>0,R35/S35-1,"") | V35: =E35=M35 -> FALSE | W35: 毛利
D36: OEM烟灶 | E36: ='4.经营实际明细S'!E40 -> 446.54259 | F36: ='4.经营实际明细S'!F40 -> 59.738539 | G36: ='4.经营实际明细S'!G40 -> 9.739013 | H36: ='4.经营实际明细S'!H40 -> 121.25174 | I36: ='4.经营实际明细S'!I40 -> 236.17152 | J36: ='4.经营实际明细S'!J40 -> 552.13777 | K36: ='4.经营实际明细S'!K40 -> 446.54259 | L36: ='4.经营实际明细S'!L40 -> 0 | ... Q36: ='4.经营实际明细S'!Q40 -> 0 | R36: =SUM(F36:Q36) -> 1425.5812 | S36: =基数汇总!S1236 -> 0 | T36: =基数汇总!R1236 -> 0 | U36: =IF(S36>0,R36/S36-1,"") | V36: =E36=M36 -> FALSE | W36: 毛利
D37: OEM其他 | E37: ='4.经营实际明细S'!E41-#REF! -> #REF! | F37: ='4.经营实际明细S'!F41-#REF! -> #REF! | G37: ='4.经营实际明细S'!G41-#REF! -> #REF! | H37: ='4.经营实际明细S'!H41-#REF! -> #REF! | I37: ='4.经营实际明细S'!I41-#REF! -> #REF! | J37: ='4.经营实际明细S'!J41-#REF! -> #REF! | K37: ='4.经营实际明细S'!K41-#REF! -> #REF! | L37: ='4.经营实际明细S'!L41-#REF! -> #REF! | ... T37: ='4.经营实际明细S'!T41-#REF! -> #REF! | U37: =IF(S37>0,R37/S37-1,"") -> #REF! | V37: =E37=M37 -> #REF! | W37: 毛利
D38: 自制烟灶 | E38: ='4.经营实际明细S'!E42 -> 253.05245 | F38: ='4.经营实际明细S'!F42 -> 50.6227 | G38: ='4.经营实际明细S'!G42 -> 1.5869 | H38: ='4.经营实际明细S'!H42 -> 115.88813 | I38: ='4.经营实际明细S'!I42 -> 185.29046 | J38: ='4.经营实际明细S'!J42 -> 343.04967 | K38: ='4.经营实际明细S'!K42 -> 253.05245 | L38: ='4.经营实际明细S'!L42 -> 0 | ... Q38: ='4.经营实际明细S'!Q42 -> 0 | R38: =SUM(F38:Q38) -> 949.4903 | S38: =基数汇总!S1238 -> 0 | T38: =基数汇总!R1238 -> 223.83993 | U38: =IF(S38>0,R38/S38-1,"") | V38: =E38=M38 -> FALSE | W38: 毛利
D39: 其他加收 | E39: ='4.经营实际明细S'!E45 -> 13.7832 | F39: ='4.经营实际明细S'!F45 -> 1.1902 | G39: ='4.经营实际明细S'!G45 -> 0.18 | H39: ='4.经营实际明细S'!H45 -> 1.2159 | I39: ='4.经营实际明细S'!I45 -> 2.5061 | J39: ='4.经营实际明细S'!J45 -> 3.3347 | K39: ='4.经营实际明细S'!K45 -> 13.7832 | L39: ='4.经营实际明细S'!L45 -> 0 | ... Q39: ='4.经营实际明细S'!Q45 -> 0 | R39: =SUM(F39:Q39) -> 22.2101 | S39: =基数汇总!S1239 -> 0 | T39: =基数汇总!R1239 -> 132.05217 | U39: =IF(S39>0,R39/S39-1,"") | V39: =E39=M39 -> FALSE | W39: 毛利
C40: 按订单类型 | D40: 常规单 | E40: ='4.经营实际明细S'!E46-#REF! -> #REF! | F40: ='4.经营实际明细S'!F46-#REF! -> #REF! | G40: ='4.经营实际明细S'!G46-#REF! -> #REF! | H40: ='4.经营实际明细S'!H46-#REF! -> #REF! | I40: ='4.经营实际明细S'!I46-#REF! -> #REF! | J40: ='4.经营实际明细S'!J46-#REF! -> #REF! | K40: ='4.经营实际明细S'!K46-#REF! -> #REF! | L40: ='4.经营实际明细S'!L46-#REF! -> #REF! | ... T40: ='4.经营实际明细S'!T46-#REF! -> #REF! | U40: =IF(S40>0,R40/S40-1,"") -> #REF! | V40: =E40=M40 -> #REF! | W40: 毛利
...

Sheet 本年累计S(集团取数)
A1: 2019年橱柜营销线本年累计报表 | V1: 返回目录 | W1: 研发中心费用分摊 | X1: 分摊率 | Y1: 分摊额
R2: 单位：万元 | X2: 0.0008 | Y2: =X2*E454 -> #REF! | Z2: =Y2*10000 -> #REF!
A3: 部门 | B3: 项目 | C3: 口径 | D3: 类别 | E3: 本月 | F3: 1月 | G3: 2月 | H3: 3月 | I3: 4月 | J3: 5月 | K3: 6月 | L3: 7月 | M3: 8月 | N3: 9月 | O3: 10月 | P3: 11月 | Q3: 12月 | R3: 本年累计 | S3: 上年同期 | T3: 上年全年 | U3: 增长率
A4: 橱柜经销一部 | B4: 收入 | C4: 按产品 | D4: 柜门 | E4: =#REF! -> #REF! | F4: 882.7972 | G4: =E4 -> #REF! | R4: =SUM(F4:Q4) -> #REF! | S4: =基数汇总!S5 -> 8008.3663 | T4: =基数汇总!R5 -> 19479.117 | U4: =IF(S4>0,R4/S4-1,"") -> #REF! | V4: =E4=M4 -> #REF!
D5: 台面 | E5: =#REF! -> #REF! | F5: 494.974 | G5: =E5 -> #REF! | R5: =SUM(F5:Q5) -> #REF! | S5: =基数汇总!S6 -> 4772.9023 | T5: =基数汇总!R6 -> 8126.7205 | U5: =IF(S5>0,R5/S5-1,"") -> #REF! | V5: =E5=M5 -> #REF!
D6: OEM烟灶 | E6: =#REF! -> #REF! | F6: 150.52394 | G6: =E6 -> #REF! | R6: =SUM(F6:Q6) -> #REF! | S6: =基数汇总!S7 -> 5848.0713 | T6: =基数汇总!R7 -> 13642.732 | U6: =IF(S6>0,R6/S6-1,"") -> #REF! | V6: =E6=M6 -> #REF!
D7: OEM其他 | E7: =#REF! -> #REF! | F7: 304.39522 | G7: =E7 -> #REF! | R7: =SUM(F7:Q7) -> #REF! | S7: =基数汇总!S8 -> 2422.6895 | T7: =基数汇总!R8 -> 6179.2907 | U7: =IF(S7>0,R7/S7-1,"") -> #REF! | V7: =E7=M7 -> #REF!
D8: 自制烟灶 | E8: =#REF! -> #REF! | F8: 109.2042 | G8: =E8 -> #REF! | R8: =SUM(F8:Q8) -> #REF! | S8: =基数汇总!S9 -> 19.3668 | T8: =基数汇总!R9 -> 43.6799 | U8: =IF(S8>0,R8/S8-1,"") -> #REF! | V8: =E8=M8 -> #REF!
D9: 其他加收 | E9: =#REF! -> #REF! | F9: 1.1902 | G9: =E9 -> #REF! | R9: =SUM(F9:Q9) -> #REF! | S9: =基数汇总!S10 -> 27296.78 | T9: =基数汇总!R10 -> 63081.624 | U9: =IF(S9>0,R9/S9-1,"") -> #REF! | V9: =E9=M9 -> #REF!
C10: 按订单类型 | D10: 常规单 | E10: =#REF! -> #REF! | F10: 1586.4041 | G10: =E10 -> #REF! | R10: =SUM(F10:Q10) -> #REF! | S10: =基数汇总!S11 -> 2410.2793 | T10: =基数汇总!R11 -> 5820.3908 | U10: =IF(S10>0,R10/S10-1,"") -> #REF! | V10: =E10=M10 -> #REF!
D11: 家装单 | E11: =#REF! -> #REF! | F11: 142.4542 | G11: =E11 -> #REF! | R11: =SUM(F11:Q11) -> #REF! | S11: =基数汇总!S12 -> 5188.4703 | T11: =基数汇总!R12 -> 13052.772 | U11: =IF(S11>0,R11/S11-1,"") -> #REF! | V11: =E11=M11 -> #REF!
D12: 直供单 | E12: =#REF! -> #REF! | F12: 195.3872 | G12: =E12 -> #REF! | R12: =SUM(F12:Q12) -> #REF! | S12: =基数汇总!S13 -> 2.8317 | T12: =基数汇总!R13 -> 2.8317 | U12: =IF(S12>0,R12/S12-1,"") -> #REF! | V12: =E12=M12 -> #REF!
D13: 网销单 | E13: =#REF! -> #REF! | F13: 0 | G13: =E13 -> #REF! | R13: =SUM(F13:Q13) -> #REF! | S13: =基数汇总!S14 -> 84.3052 | T13: =基数汇总!R14 -> 487.9132 | U13: =IF(S13>0,R13/S13-1,"") -> #REF! | V13: =E13=M13 -> #REF!
D14: 星居单 | E14: =#REF! -> #REF! | F14: 11.9667 | G14: =E14 -> #REF! | R14: =SUM(F14:Q14) -> #REF! | S14: =基数汇总!S15 -> 1.2518 | T14: =基数汇总!R15 -> 31.3682 | U14: =IF(S14>0,R14/S14-1,"") -> #REF! | V14: =E14=M14 -> #REF!
D15: 微居单 | E15: =#REF! -> #REF! | F15: 6.8726 | G15: =E15 -> #REF! | R15: =SUM(F15:Q15) -> #REF! | S15: =基数汇总!S16 -> 30665.388 | T15: =基数汇总!R16 -> 72663.356 | U15: =IF(S15>0,R15/S15-1,"") -> #REF! | V15: =E15=M15 -> #REF!
C16: 按合同类型 | D16: 普通单 | E16: =#REF! -> #REF! | F16: 1757.8627 | G16: =E16 -> #REF! | R16: =SUM(F16:Q16) -> #REF! | S16: =基数汇总!S17 -> 3964.233 | T16: =基数汇总!R17 -> 9004.57 | U16: =IF(S16>0,R16/S16-1,"") -> #REF! | V16: =E16=M16 -> #REF!
D17: 样品单 | E17: =#REF! -> #REF! | F17: 185.22204 | G17: =E17 -> #REF! | R17: =SUM(F17:Q17) -> #REF! | S17: =基数汇总!S18 -> 354.2968 | T17: =基数汇总!R18 -> 808.9736 | U17: =IF(S17>0,R17/S17-1,"") -> #REF! | V17: =E17=M17 -> #REF!
D18: 遗留单 | E18: =#REF! -> #REF! | F18: 0 | G18: =E18 -> #REF! | R18: =SUM(F18:Q18) -> #REF! | S18: =基数汇总!S19 -> 10238.253 | T18: =基数汇总!R19 -> 25159.912 | U18: =IF(S18>0,R18/S18-1,"") -> #REF! | V18: =E18=M18 -> #REF!
B19: 成本 | C19: 按产品 | D19: 柜门 | E19: =#REF! -> #REF! | F19: 766.52129 | G19: =E19 -> #REF! | R19: =SUM(F19:Q19) -> #REF! | S19: =基数汇总!S20 -> 5893.369 | T19: =基数汇总!R20 -> 14003.794 | U19: =IF(S19>0,R19/S19-1,"") -> #REF! | V19: =E19=M19 -> #REF!
D20: 台面 | E20: =#REF! -> #REF! | F20: 424.7822 | G20: =E20 -> #REF! | R20: =SUM(F20:Q20) -> #REF! | S20: =基数汇总!S21 -> 3136.8449 | T20: =基数汇总!R21 -> 5425.4738 | U20: =IF(S20>0,R20/S20-1,"") -> #REF! | V20: =E20=M20 -> #REF!
D21: OEM烟灶 | E21: =#REF! -> #REF! | F21: 90.785403 | G21: =E21 -> #REF! | R21: =SUM(F21:Q21) -> #REF! | S21: =基数汇总!S22 -> 3433.1215 | T21: =基数汇总!R22 -> 8348.9275 | U21: =IF(S21>0,R21/S21-1,"") -> #REF! | V21: =E21=M21 -> #REF!
D22: OEM其他 | E22: =#REF! -> #REF! | F22: 183.52541 | G22: =E22 -> #REF! | R22: =SUM(F22:Q22) -> #REF! | S22: =基数汇总!S23 -> 1337.6848 | T22: =基数汇总!R23 -> 3464.7832 | U22: =IF(S22>0,R22/S22-1,"") -> #REF! | V22: =E22=M22 -> #REF!
D23: 自制烟灶 | E23: =#REF! -> #REF! | F23: 58.5815 | G23: =E23 -> #REF! | R23: =SUM(F23:Q23) -> #REF! | S23: =基数汇总!S24 -> 0 | T23: =基数汇总!R24 -> 0 | U23: =IF(S23>0,R23/S23-1,"") | V23: =E23=M23 -> #REF!
D24: 其他加收 | E24: =#REF! -> #REF! | F24: 0 | G24: =E24 -> #REF! | R24: =SUM(F24:Q24) -> #REF! | S24: =基数汇总!S25 -> 17980.048 | T24: =基数汇总!R25 -> 41649.545 | U24: =IF(S24>0,R24/S24-1,"") -> #REF! | V24: =E24=M24 -> #REF!
C25: 按订单类型 | D25: 常规单 | E25: =#REF! -> #REF! | F25: 1215.9836 | G25: =E25 -> #REF! | R25: =SUM(F25:Q25) -> #REF! | S25: =基数汇总!S26 -> 2065.6359 | T25: =基数汇总!R26 -> 4768.7604 | U25: =IF(S25>0,R25/S25-1,"") -> #REF! | V25: =E25=M25 -> #REF!
D26: 家装单 | E26: =#REF! -> #REF! | F26: 123.92445 | G26: =E26 -> #REF! | R26: =SUM(F26:Q26) -> #REF! | S26: =基数汇总!S27 -> 3924.6917 | T26: =基数汇总!R27 -> 9595.2209 | U26: =IF(S26>0,R26/S26-1,"") -> #REF! | V26: =E26=M26 -> #REF!
D27: 直供单 | E27: =#REF! -> #REF! | F27: 167.44724 | G27: =E27 -> #REF! | R27: =SUM(F27:Q27) -> #REF! | S27: =基数汇总!S28 -> 2.1537271 | T27: =基数汇总!R28 -> 2.1537271 | U27: =IF(S27>0,R27/S27-1,"") -> #REF! | V27: =E27=M27 -> #REF!
D28: 网销单 | E28: =#REF! -> #REF! | F28: 0 | G28: =E28 -> #REF! | R28: =SUM(F28:Q28) -> #REF! | S28: =基数汇总!S29 -> 65.722569 | T28: =基数汇总!R29 -> 362.30406 | U28: =IF(S28>0,R28/S28-1,"") -> #REF! | V28: =E28=M28 -> #REF!
D29: 星居单 | E29: =#REF! -> #REF! | F29: 10.204182 | G29: =E29 -> #REF! | R29: =SUM(F29:Q29) -> #REF! | S29: =基数汇总!S30 -> 1.0219387 | T29: =基数汇总!R30 -> 24.905507 | U29: =IF(S29>0,R29/S29-1,"") -> #REF! | V29: =E29=M29 -> #REF!
D30: 微居单 | E30: =#REF! -> #REF! | F30: 6.6363377 | G30: =E30 -> #REF! | R30: =SUM(F30:Q30) -> #REF! | S30: =基数汇总!S31 -> 20741.544 | T30: =基数汇总!R31 -> 49011.837 | U30: =IF(S30>0,R30/S30-1,"") -> #REF! | V30: =E30=M30 -> #REF!
C31: 按合同类型 | D31: 普通单 | E31: =#REF! -> #REF! | F31: 1352.0501 | G31: =E31 -> #REF! | R31: =SUM(F31:Q31) -> #REF! | S31: =基数汇总!S32 -> 2999.7662 | T31: =基数汇总!R32 -> 6699.8069 | U31: =IF(S31>0,R31/S31-1,"") -> #REF! | V31: =E31=M31 -> #REF!
D32: 样品单 | E32: =#REF! -> #REF! | F32: 162.96283 | G32: =E32 -> #REF! | R32: =SUM(F32:Q32) -> #REF! | S32: =基数汇总!S33 -> 297.96354 | T32: =基数汇总!R33 -> 691.24638 | U32: =IF(S32>0,R32/S32-1,"") -> #REF! | V32: =E32=M32 -> #REF!
D33: 遗留单 | E33: =#REF! -> #REF! | F33: 9.182839 | G33: =E33 -> #REF! | R33: =SUM(F33:Q33) -> #REF! | S33: =基数汇总!S34 -> 3674.2684 | T33: =基数汇总!R34 -> 9837.228 | U33: =IF(S33>0,R33/S33-1,"") -> #REF! | V33: =E33=M33 -> #REF!
B34: 毛利 | C34: 按产品 | D34: 柜门 | E34: =#REF! -> #REF! | F34: 116.27591 | G34: =E34 -> #REF! | R34: =SUM(F34:Q34) -> #REF! | S34: =基数汇总!S35 -> 2114.9973 | T34: =基数汇总!R35 -> 5475.3232 | U34: =IF(S34>0,R34/S34-1,"") -> #REF! | V34: =E34=M34 -> #REF!
D35: 台面 | E35: =#REF! -> #REF! | F35: 70.191796 | G35: =E35 -> #REF! | R35: =SUM(F35:Q35) -> #REF! | S35: =基数汇总!S36 -> 1636.0574 | T35: =基数汇总!R36 -> 2701.2466 | U35: =IF(S35>0,R35/S35-1,"") -> #REF! | V35: =E35=M35 -> #REF!
D36: OEM烟灶 | E36: =#REF! -> #REF! | F36: 59.738539 | G36: =E36 -> #REF! | R36: =SUM(F36:Q36) -> #REF! | S36: =基数汇总!S37 -> 2414.9498 | T36: =基数汇总!R37 -> 5293.8046 | U36: =IF(S36>0,R36/S36-1,"") -> #REF! | V36: =E36=M36 -> #REF!
D37: OEM其他 | E37: =#REF! -> #REF! | F37: 120.86981 | G37: =E37 -> #REF! | R37: =SUM(F37:Q37) -> #REF! | S37: =基数汇总!S38 -> 1085.0047 | T37: =基数汇总!R38 -> 2714.5076 | U37: =IF(S37>0,R37/S37-1,"") -> #REF! | V37: =E37=M37 -> #REF!
D38: 自制烟灶 | E38: =#REF! -> #REF! | F38: 50.6227 | G38: =E38 -> #REF! | R38: =SUM(F38:Q38) -> #REF! | S38: =基数汇总!S39 -> 19.3668 | T38: =基数汇总!R39 -> 43.6799 | U38: =IF(S38>0,R38/S38-1,"") -> #REF! | V38: =E38=M38 -> #REF!
D39: 其他加收 | E39: =#REF! -> #REF! | F39: 1.1902 | G39: =E39 -> #REF! | R39: =SUM(F39:Q39) -> #REF! | S39: =基数汇总!S40 -> 9316.7319 | T39: =基数汇总!R40 -> 21432.078 | U39: =IF(S39>0,R39/S39-1,"") -> #REF! | V39: =E39=M39 -> #REF!
C40: 按订单类型 | D40: 常规单 | E40: =#REF! -> #REF! | F40: 370.42047 | G40: =E40 -> #REF! | R40: =SUM(F40:Q40) -> #REF! | S40: =基数汇总!S41 -> 344.64339 | T40: =基数汇总!R41 -> 1051.6304 | U40: =IF(S40>0,R40/S40-1,"") -> #REF! | V40: =E40=M40 -> #REF!
...

Sheet 制表备注
C1: B
A2: =#REF!&"橱柜营销线财务报表目录" -> #REF!
A4: 序号 | B4: 名 称 | C4: 页码 | D4: 备注 | E4: 更新1 | F4: 更新2 | G4: 更新3 | H4: 更新4 | I4: 更新5 | J4: 更新6 | K4: 更新7
A5: 1 | B5: 橱柜营销线M/N值目标完成、增长考核情况 ．．．．．．．．．．．．．．．．．．． | C5: 1 | D5: 考核 | E5: 无
A6: 2 | B6: 橱柜营销线M/N值经营简报 ．．．．．．．．．．．．．．．．．．． | C6: 1.1 | D6: 考核 | E6: 更新截止前一个月的累计数 | F6: 当月取数公式更改 | G6: 上月数据
A7: 3 | B7: 橱柜营销线考核调整汇总表．．．．．．．．．．．．．．．．．．．．． | C7: 2 | D7: 考核 | E7: 无
A8: 4 | B8: 橱柜营销线调整月度表 ．．．．．．．．．．．．．．．．．．．．．． | C8: 2.1 | D8: 考核，不发送 | E8: 工程共享 | F8: 大礼包（取百货报表） | G8: 广分专项 | H8: 电器厂共享 | I8: 整装大家居收入、厨电售服共享 | J8: 欧铂丽厨电售服专项
A9: 5 | B9: 橱柜营销线调整累计表 ．．．．．．．．．．．．．．．．．．．．．． | C9: 2.2 | D9: 考核，不发送 | E9: 无
A10: 6 | B10: 橱柜营销线实际经营情况汇总表．．．．．．．．．．．．．．．．．．．．．．．．．．．． | C10: 3 | D10: 实际表 | E10: 无
A11: 7 | B11: 橱柜营销线实际经营情况明细表．．．．．．．．．．．．．．．．．．．．．．．．．．．．． | C11: 4 | D11: 实际表 | E11: 简要分析上月取数更新 | F11: 当月取数公式更改
A12: 8 | B12: 橱柜营销线各部门费用实际总表．．．．．．．．．．．．．．．．．．．．． | C12: 5 | D12: 实际表 | E12: 无
A13: 9 | B13: 橱柜营销线各部门费用实际明细表1．．．．．．．．．．．．．．．．．．． | C13: 5.1 | D13: 实际表 | E13: 无
A14: 10 | B14: 橱柜营销线各部门费用实际明细表1．．．．．．．．．．．．．．．．．．． | C14: 5.2 | D14: 实际表 | E14: 上月实际发生额 | F14: 当月取数公式更改 | G14: 上月更新
A15: 11 | B15: 2018年橱柜营销专项费用提取及支出汇总考核表．．．．．．．．．．．．．．． | C15: 6 | D15: 考核 | E15: 无
A16: 12 | B16: 资产占用统计及各部应收账款分类汇总表．．．．．．．．．．．．．．．．．．．．．．．．．． | C16: 7 | D16: 实际表 | E16: 资产占用 | F16: 应收账款分类汇总 | G16: 应付账款
A17: 13 | B17: 橱柜营销线各部月度汇总实际表 ．．．．．．．．．．．．．．．．．．．．．． | C17: 8 | D17: 实际表 | E17: 当月取数公式更改
A18: 14 | B18: 橱柜营销线各部利润实际表 ．．．．．．．．．．．．．．．．．．．．．．．．．．．．．．．． | C18: 9 | D18: 实际表 | E18: 其他加收 | F18: 星居单、微居单数值更新 | G18: 上月合计
A19: 15 | B19: 经销部收入成本（厂部级）及专项费用计提明细实际表．．．．．．．．．．．． | C19: 10 | D19: 实际表 | E19: 经销部收入①
A20: 16 | B20: 橱柜经销部毛利率调整表．．．．．．．．．．．．．．．．．．．．．．．．．． | C20: 11 | D20: 实际表 | E20: 上月收入、成本拉公式
A21: 17 | B21: 橱柜营销线百货收入、成本明细表．．．．．．．．．．．．．．．．．．．．． | C21: 12 | D21: 实际表 | E21: 百货收入+成本 | F21: 上月数据数值填入，本月公式更改
A22: 18 | B22: 2018年橱柜营销专项费用提取及支出汇总实际表．．．．．．．．．．．．．．． | C22: 13 | D22: 实际表 | E22: 专项费用引数-支出 | F22: 当月取数公式更改 | G22: 品牌中心专项提取支付结余更新 | H22: 衣柜提取品牌中心额 | I22: 星居微居提取取数-S9
A23: 19 | B23: 费用取数 | C23: 14 | E23: 费用取数 | G23: 提取物流运费（台面、百货、橱柜收入）+橱柜厂收入分配比例 | H23: 净水器收入 | I23: 方太林内3M以及触摸茶几等产品不承担税款等费用
A24: 20 | B24: 折前及其他取数 | C24: 15 | E24: 期间、折前 | F24: 经销商会议费用，衣柜收入 | H24: 期末库存商品余额 | J24: 研发中心费用分摊计算挂账
B25: 基数汇总 | E25: 同期填“是” | F25: 更新本月

Sheet 0.报表目录
C1: B
A2: =#REF!&"橱柜营销线财务报表目录" -> #REF!
A4: 序号 | B4: 名 称 | C4: 页码 | D4: 备注
A5: 1 | B5: 橱柜营销线M/N值目标完成、增长考核情况 ．．．．．．．．．．．．．．．．．．． | C5: 1 | D5: 考核
A6: 2 | B6: 橱柜营销线M/N值经营简报 ．．．．．．．．．．．．．．．．．．． | C6: 1.1 | D6: 考核
A7: 3 | B7: 橱柜营销线考核调整汇总表．．．．．．．．．．．．．．．．．．．．． | C7: 2 | D7: 实际表
A8: 4 | B8: 橱柜营销线调整月度表 ．．．．．．．．．．．．．．．．．．．．．． | C8: 2.1 | D8: 调整表
A9: 5 | B9: 橱柜营销线调整累计表 ．．．．．．．．．．．．．．．．．．．．．． | C9: 2.2 | D9: 调整表
A10: 6 | B10: 橱柜营销线实际经营情况汇总表．．．．．．．．．．．．．．．．．．．．．．．．．．．． | C10: 3 | D10: 实际表
A11: 7 | B11: 橱柜营销线实际经营情况明细表．．．．．．．．．．．．．．．．．．．．．．．．．．．．． | C11: 4 | D11: 实际表
A12: 8 | B12: 橱柜营销线各部门费用实际总表．．．．．．．．．．．．．．．．．．．．． | C12: 5 | D12: 实际表
A13: 9 | B13: 橱柜营销线各部门费用实际明细表1．．．．．．．．．．．．．．．．．．． | C13: 5.1 | D13: 实际表
A14: 10 | B14: 橱柜营销线各部门费用实际明细表1．．．．．．．．．．．．．．．．．．． | C14: 5.2 | D14: 实际表
A15: 11 | B15: 2018年橱柜营销专项费用提取及支出汇总考核表．．．．．．．．．．．．．．． | C15: 6 | D15: 考核
A16: 12 | B16: 资产占用统计及各部应收账款分类汇总表．．．．．．．．．．．．．．．．．．．．．．．．．． | C16: 7 | D16: 考核
A17: 13 | B17: 橱柜营销线各部月度汇总实际表 ．．．．．．．．．．．．．．．．．．．．．． | C17: 8 | D17: 实际表
A18: 14 | B18: 橱柜营销线各部利润实际表 ．．．．．．．．．．．．．．．．．．．．．．．．．．．．．．．． | C18: 9 | D18: 实际表
A19: 15 | B19: 经销部收入成本（厂部级）及专项费用计提明细实际表．．．．．．．．．．．． | C19: 10 | D19: 实际表
A20: 16 | B20: 橱柜经销部毛利率调整表．．．．．．．．．．．．．．．．．．．．．．．．．． | C20: 11 | D20: 实际表
A21: 17 | B21: 橱柜营销线百货收入、成本明细表．．．．．．．．．．．．．．．．．．．．． | C21: 12 | D21: 实际表
A22: 18 | B22: 2018年橱柜营销专项费用提取及支出汇总实际表．．．．．．．．．．．．．．． | C22: 13 | D22: 实际表

Sheet 1.考核完成增长K
A1: 橱柜营销线M/N值目标完成/增长情况
A2: 表1.橱柜营销线M/N值完成汇总 | I2: （截止到2020年6月止） | Q2: 单位:万元
A3: 序号 | B3: 部门 | C3: 口径 | D3: M值指标情况 | K3: N值指标情况
D4: 本年M值累计 | E4: M值同期基数 | F4: M值增长率 | G4: M值基数 | H4: M值目标增长率 | I4: M值期望目标 | J4: M值完成率 | K4: 本年N值累计 | L4: N值同期基数 | M4: N值增长率 | N4: N值基数 | O4: N值目标增长率 | P4: N值期望目标 | Q4: N值完成率
A5: 1 | B5: 橱柜经销一部 | C5: 实际 | D5: 5798.2438 | E5: 6743.8171 | F5: -0.14021337 | G5: 14990.709 | H5: 0.0041099455 | I5: 15052.32 | J5: 0.38520599 | K5: 28052.142 | L5: 34983.918 | M5: -0.19814178 | N5: 82468.68 | O5: -0.0093089758 | P5: 81700.981 | Q5: 0.34335135
A6: 2 | B6: 橱柜经销一部 | C6: 调整 | D6: -4.1608366 | E6: -10.625036 | G6: -21.876391 | I6: -21.876391 | K6: -20.27 | L6: -56.285 | N6: -108.71 | P6: -108.71
A7: 3 | B7: 橱柜经销一部 | C7: 考核 | D7: 5794.083 | E7: 6733.1921 | F7: -0.13947458 | G7: 14968.833 | H7: 0.0041 | I7: 15030.205 | J7: 0.38549594 | K7: 28031.872 | L7: 34927.633 | M7: -0.19742995 | N7: 82359.97 | O7: -0.0093 | P7: 81594.022 | Q7: 0.34355302
A8: 4 | B8: 橱柜经销二部 | C8: 实际 | D8: 4648.8235 | E8: 5340.7969 | F8: -0.1295637 | G8: 12366.631 | H8: 0.0041099455 | I8: 12417.458 | J8: 0.37437804 | K8: 23097.513 | L8: 29698.691 | M8: -0.22227169 | N8: 70452.238 | O8: -0.0093089758 | P8: 69796.4 | Q8: 0.33092699
A9: 5 | B9: 橱柜经销二部 | C9: 调整 | D9: -7.9441921 | E9: -17.890177 | G9: -34.466063 | I9: -34.466063 | K9: -37.526 | L9: -83.035 | N9: -166.32 | P9: -166.32
A10: 6 | B10: 橱柜经销二部 | C10: 考核 | D10: 4640.8793 | E10: 5322.9067 | F10: -0.12813063 | G10: 12332.165 | H10: 0.0041 | I10: 12382.727 | J10: 0.37478652 | K10: 23059.987 | L10: 29615.656 | M10: -0.22135823 | N10: 70285.918 | O10: -0.0093 | P10: 69632.259 | Q10: 0.33116815
A11: 7 | B11: 橱柜经销三分部 | C11: 实际 | D11: 3697.6374 | E11: 4196.3637 | F11: -0.11884724 | G11: 11698.717 | H11: 0.0041099455 | I11: 11746.799 | J11: 0.31477831 | K11: 18210.534 | L11: 25711.765 | M11: -0.29174314 | N11: 64704.91 | O11: -0.0093089758 | P11: 64102.573 | Q11: 0.28408429
A12: 8 | B12: 橱柜经销三分部 | C12: 调整 | D12: -7.0720603 | E12: -6.859995 | G12: -18.413557 | I12: -18.413557 | K12: -31.782 | L12: -34.11 | N12: -87.749 | P12: -87.749
A13: 9 | B13: 橱柜经销三分部 | C13: 考核 | D13: 3690.5654 | E13: 4189.5037 | F13: -0.11909246 | G13: 11680.304 | H13: 0.0041 | I13: 11728.193 | J13: 0.31467468 | K13: 18178.752 | L13: 25677.655 | M13: -0.29204002 | N13: 64617.161 | O13: -0.0093 | P13: 64016.221 | Q13: 0.28397103
A14: 10 | B14: 橱柜经销四部 | C14: 实际 | D14: 4327.0107 | E14: 4973.6975 | F14: -0.13002134 | G14: 12782.294 | H14: 0.0041099455 | I14: 12834.828 | J14: 0.33713039 | K14: 20873.436 | L14: 26196.534 | M14: -0.20319855 | N14: 69663.005 | O14: -0.0093089758 | P14: 69014.513 | Q14: 0.30244995
A15: 11 | B15: 橱柜经销四部 | C15: 调整 | D15: -2.3570108 | E15: -6.240514 | G15: -12.680023 | I15: -12.680023 | K15: -11.11 | L15: -31.12 | N15: -60.495 | P15: -60.495
A16: 12 | B16: 橱柜经销四部 | C16: 考核 | D16: 4324.6537 | E16: 4967.457 | F16: -0.12940289 | G16: 12769.614 | H16: 0.0041 | I16: 12821.969 | J16: 0.33728467 | K16: 20862.326 | L16: 26165.414 | M16: -0.20267548 | N16: 69602.51 | O16: -0.0093 | P16: 68955.206 | Q16: 0.30254896
A17: 13 | B17: 橱柜经销五部 | C17: 实际 | D17: 5581.4423 | E17: 6497.1637 | F17: -0.14094172 | G17: 16134.395 | H17: 0.0041099455 | I17: 16200.707 | J17: 0.34451844 | K17: 28031.151 | L17: 39916.611 | M17: -0.29775725 | N17: 95253.222 | O17: -0.0093089758 | P17: 94366.512 | Q17: 0.29704553
A18: 14 | B18: 橱柜经销五部 | C18: 调整 | D18: -7.3960555 | E18: -26.393148 | G18: -60.236365 | I18: -60.236365 | K18: -34.9 | L18: -101.705 | N18: -253.2 | P18: -253.2
A19: 15 | B19: 橱柜经销五部 | C19: 考核 | D19: 5574.0462 | E19: 6470.7706 | F19: -0.13858077 | G19: 16074.159 | H19: 0.0041 | I19: 16140.063 | J19: 0.34535468 | K19: 27996.251 | L19: 39814.906 | M19: -0.29683997 | N19: 95000.022 | O19: -0.0093 | P19: 94116.522 | Q19: 0.29746372
A20: 16 | B20: 橱柜经销六部 | C20: 实际 | D20: 5625.8334 | E20: 6769.6276 | F20: -0.1689597 | G20: 16410.992 | H20: 0.0041099455 | I20: 16478.44 | J20: 0.3414057 | K20: 27376.096 | L20: 37363.067 | M20: -0.26729525 | N20: 93349.846 | O20: -0.0093089758 | P20: 92480.855 | Q20: 0.29601907
A21: 17 | B21: 橱柜经销六部 | C21: 调整 | D21: -4.3683337 | E21: -22.791248 | G21: -44.010662 | I21: -44.010662 | K21: -21.065 | L21: -112.88 | N21: -210.155 | P21: -210.155
A22: 18 | B22: 橱柜经销六部 | C22: 考核 | D22: 5621.4651 | E22: 6746.8364 | F22: -0.16679985 | G22: 16366.981 | H22: 0.0041 | I22: 16434.086 | J22: 0.34206132 | K22: 27355.031 | L22: 37250.187 | M22: -0.26564042 | N22: 93139.691 | O22: -0.0093 | P22: 92273.492 | Q22: 0.29645601
A23: 19 | B23: 厨电百货经销部-直售 | C23: 实际 | D23: 287.06527 | E23: 121.49744 | F23: 1.3627269 | G23: 510.46559 | H23: 0.0041099455 | I23: 512.56358 | J23: 0.56005787 | K23: 601.7148 | L23: 232.32547 | M23: 1.5899649 | N23: 1043.0983 | O23: -0.0093089758 | P23: 1033.3882 | Q23: 0.58227375
A24: 20 | B24: 厨电百货经销部-直售 | C24: 调整 | D24: 0 | I24: 0 | K24: 0 | L24: 0 | P24: 0
A25: 21 | B25: 厨电百货经销部-直售 | C25: 考核 | D25: 287.06527 | E25: 121.49744 | F25: 1.3627269 | G25: 510.46559 | H25: 0.0041 | I25: 512.5585 | J25: 0.56006342 | K25: 601.7148 | L25: 232.32547 | M25: 1.5899649 | N25: 1043.0983 | O25: -0.0093 | P25: 1033.3975 | Q25: 0.58226847
A26: 22 | B26: 橱柜营销利润中心合计① | C26: 实际 | D26: 29966.056 | E26: 34642.964 | F26: -0.1350031 | G26: 84894.205 | H26: 0.0041099455 | I26: 85243.115 | J26: 0.35153638 | K26: 146242.59 | L26: 194102.91 | M26: -0.2465719 | N26: 476935 | O26: -0.0093089758 | P26: 472495.22 | Q26: 0.30951125
A27: 23 | B27: 橱柜营销利润中心合计① | C27: 调整 | D27: -33.298489 | E27: -90.800118 | G27: -191.68306 | I27: -191.68306 | K27: -156.653 | L27: -419.135 | N27: -886.629 | O27: -0.0093089758 | P27: -878.37539
A28: 24 | B28: 橱柜营销利润中心合计① | C28: 考核 | D28: 29932.758 | E28: 34552.164 | F28: -0.13369368 | G28: 84702.522 | H28: 0.0041 | I28: 85049.802 | J28: 0.35194389 | K28: 146085.93 | L28: 193683.78 | M28: -0.24575028 | N28: 476048.37 | O28: -0.0093 | P28: 471621.12 | Q28: 0.30975274
A29: 25 | B29: 橱柜培训部 | C29: 实际 | D29: -223.78649 | E29: -450.1335 | G29: -1176.2379 | H29: 0.0041099455 | I29: -1181.0721 | P29: 0
A30: 26 | B30: 橱柜营销服务支持部 | C30: 实际 | D30: -176.80559 | E30: -230.67359 | G30: -495.1757 | H30: 0.0041099455 | I30: -497.21084 | P30: 0
A31: 27 | B31: 橱柜展示设计部 | C31: 实际 | D31: -300.30239 | E31: 10.255859 | F31: -30.281055 | G31: 55.524474 | H31: 0.0041099455 | I31: 55.752677 | J31: -5.3863313 | P31: 0
A32: 28 | B32: 厨电百货售后服务部 | C32: 实际 | D32: -98.585182 | E32: -180.50311 | G32: -808.58673 | H32: 0.0041099455 | I32: -811.90998 | P32: 0
A33: 29 | B33: 橱柜招商部 | C33: 实际 | D33: -492.38563 | E33: -465.6198 | G33: -1306.662 | H33: 0.0041099455 | I33: -1312.0324 | P33: 0
A34: 30 | B34: 厨电百货供应服务分部 | C34: 实际 | D34: 333.1298 | E34: 148.10653 | F34: 1.249258 | G34: -37.596115 | H34: 0.0041099455 | I34: -37.750633 | P34: 0
A35: 31 | B35: 橱柜营销数据支部 | C35: 实际 | D35: -36.603131 | E35: -41.809626 | G35: -107.95063 | H35: 0.0041099455 | I35: -108.3943 | P35: 0
A36: 32 | B36: 橱柜市场部 | C36: 实际 | D36: -199.25518 | E36: -245.95407 | G36: -624.83678 | H36: 0.0041099455 | I36: -627.40482 | P36: 0
A37: 33 | B37: 橱柜主动营销部 | C37: 实际 | D37: -72.301327 | E37: -52.505171 | G37: -180.13542 | H37: 0.0041099455 | I37: -180.87577 | P37: 0
A38: 34 | B38: 橱柜渠道拓展部 | C38: 实际 | D38: -252.27178 | E38: -359.63762 | G38: -826.2636 | H38: 0.0041099455 | I38: -829.6595 | P38: 0
A39: 35 | B39: 橱柜电商及信息化推广分部 | C39: 实际 | D39: -70.955417 | E39: -136.72458 | G39: -303.14818 | H39: 0.0041099455 | I39: -304.3941 | P39: 0
A40: 36 | B40: 厨电百货经销部 | C40: 实际 | D40: -836.7695 | E40: -540.7618 | G40: -1838.6804 | H40: 0.0041099455 | I40: -1846.2373 | P40: 0
...

Sheet 1.1经营简报
A1: 橱柜营销线经营简报（2020年6月）
I2: 是 | J2: 是 | K2: 是 | L2: 是 | M2: 是 | N2: 是 | O2: 是 | P2: 是 | Q2: 是 | R2: 是 | S2: 是 | T2: 是 | U2: 是 | V2: 是 | W2: 是 | AV2: 单位：万元
A3: 项目 | C3: 1-5月累计 | F3: 当月 | I3: 1月 | L3: 2月 | O3: 3月 | R3: 4月 | U3: 5月 | X3: 6月 | AA3: 7月 | AD3: 8月 | AG3: 9月 | AJ3: 10月 | AM3: 11月 | AP3: 12月 | AS3: 本年累计 | AV3: 考核目标 | AW3: 目标差异 | AY3: 上月
C4: 实际 | D4: 调整 | E4: 考核 | F4: 实际 | G4: 调整 | H4: 考核 | I4: 实际 | J4: 调整 | K4: 考核 | L4: 实际 | M4: 调整 | N4: 考核 | O4: 实际 | P4: 调整 | Q4: 考核 | R4: 实际 | S4: 调整 | T4: 考核 | U4: 实际 | V4: 调整 | W4: 考核 | X4: 实际 | Y4: 调整 | Z4: 考核 | AA4: 实际 | AB4: 调整 | AC4: 考核 | AD4: 实际 | AE4: 调整 | AF4: 考核 | AG4: 实际 | AH4: 调整 | AI4: 考核 | AJ4: 实际 | AK4: 调整 | AL4: 考核 | AM4: 实际 | AN4: 调整 | AO4: 考核 | AP4: 实际 | AQ4: 调整 | AR4: 考核 | AS4: 实际 | AT4: 调整 | AU4: 考核 | AY4: 实际 | AZ4: 调整 | BA4: 考核
A5: 收入 | B5: 20年 | C5: 103126.72 | D5: 49052.333 | E5: 152179.05 | F5: 43115.865 | G5: 18999.793 | H5: 62115.658 | I5: 10735.966 | J5: 8870.4761 | K5: 19606.442 | L5: 3184.1495 | M5: 693.60293 | N5: 3877.7525 | O5: 19826.253 | P5: 8803.2275 | Q5: 28629.48 | R5: 28797.799 | S5: 13248.79 | T5: 42046.59 | U5: 40582.555 | V5: 17436.236 | W5: 58018.791 | X5: 43115.865 | Y5: 18999.793 | Z5: 62115.658 | AS5: 146242.59 | AT5: 68052.126 | AU5: 214294.71 | AY5: 40582.555 | AZ5: 17436.236 | BA5: 58018.791 | BB5: 0.062423617
B6: 19年 | C6: 146275.27 | D6: 55105.054 | E6: 201380.33 | F6: 47827.638 | G6: 19321.227 | H6: 67148.864 | I6: 29026.42 | J6: 9544.7776 | K6: 38571.198 | L6: 9470.5408 | M6: 3377.1911 | N6: 12847.732 | O6: 27974.577 | P6: 12560.083 | Q6: 40534.66 | R6: 37940.902 | S6: 13151.869 | T6: 51092.771 | U6: 41862.833 | V6: 16471.133 | W6: 58333.966 | X6: 47827.638 | Y6: 19321.227 | Z6: 67148.864 | AS6: 194102.91 | AT6: 74426.28 | AU6: 268529.19 | AY6: 41862.833 | AZ6: 16471.133 | BA6: 58333.966 | BB6: 0.1424845
B7: 增长率 | C7: -0.29498185 | D7: -0.10983967 | E7: -0.24432015 | F7: -0.098515693 | G7: -0.016636292 | H7: -0.074955943 | I7: -0.63013126 | J7: -0.070646121 | K7: -0.49168181 | L7: -0.66378377 | M7: -0.79462135 | N7: -0.6981761 | O7: -0.29127605 | P7: -0.29911073 | Q7: -0.29370371 | R7: -0.24098275 | S7: 0.0073694085 | T7: -0.17705404 | U7: -0.030582686 | V7: 0.058593584 | W7: -0.0054029444 | X7: -0.098515693 | Y7: -0.016636292 | Z7: -0.074955943 | AS7: -0.2465719 | AT7: -0.085643869 | AU7: -0.20196865 | AV7: 0.0515 | AW7: -0.25346865 | AY7: -0.030582686 | AZ7: 0.058593584 | BA7: -0.0054029444
A8: 成本 | B8: 20年 | C8: 68631.699 | D8: 49074.657 | E8: 117706.36 | F8: 28592.991 | G8: 19010.767 | H8: 47603.758 | I8: 7026.1351 | J8: 8878.4609 | K8: 15904.596 | L8: 2547.1396 | M8: 694.41732 | N8: 3241.5569 | O8: 13532.488 | P8: 8806.8365 | Q8: 22339.325 | R8: 19283.709 | S8: 13254.916 | T8: 32538.625 | U8: 26242.227 | V8: 17440.026 | W8: 43682.254 | X8: 28592.991 | Y8: 19010.767 | Z8: 47603.758 | AS8: 97224.69 | AT8: 68085.424 | AU8: 165310.11 | AY8: 26242.227 | AZ8: 17440.026 | BA8: 43682.254
B9: 19年 | C9: 100783.1 | D9: 55191.236 | E9: 155974.34 | F9: 32242.425 | G9: 19325.845 | H9: 51568.269 | I9: 20135.247 | J9: 9571.6568 | K9: 29706.904 | L9: 6932.2042 | M9: 3389.4892 | N9: 10321.693 | O9: 19493.815 | P9: 12573.761 | Q9: 32067.576 | R9: 24281.099 | S9: 13161.826 | T9: 37442.925 | U9: 29940.74 | V9: 16494.502 | W9: 46435.243 | X9: 32242.425 | Y9: 19325.845 | Z9: 51568.269 | AS9: 133025.53 | AT9: 74517.08 | AU9: 207542.61 | AY9: 29940.74 | AZ9: 16494.502 | BA9: 46435.243
B10: 增长率 | C10: -0.31901583 | D10: -0.11082518 | E10: -0.24534794 | F10: -0.11318732 | G10: -0.016303442 | H10: -0.076878892 | I10: -0.65105295 | J10: -0.072421721 | K10: -0.46461617 | L10: -0.63256426 | M10: -0.79512626 | N10: -0.68594718 | O10: -0.30580605 | P10: -0.29958614 | Q10: -0.30336721 | R10: -0.20581399 | S10: 0.0070727423 | T10: -0.13098068 | U10: -0.12352776 | V10: 0.057323559 | W10: -0.059286629 | X10: -0.11318732 | Y10: -0.016303442 | Z10: -0.076878892 | AS10: -0.26912758 | AT10: -0.086311168 | AU10: -0.20348831 | AY10: -0.12352776 | AZ10: 0.057323559 | BA10: -0.059286629
A11: 毛利 | B11: 20年 | C11: 34495.023 | D11: -22.324757 | E11: 34472.698 | F11: 14522.874 | G11: -10.973732 | H11: 14511.9 | I11: 3709.8305 | J11: -7.984862 | K11: 3701.8456 | L11: 637.00996 | M11: -0.814392 | N11: 636.19557 | O11: 6293.7644 | P11: -3.609011 | Q11: 6290.1554 | R11: 9514.0902 | S11: -6.126068 | T11: 9507.9642 | U11: 14340.328 | V11: -3.790424 | W11: 14336.537 | X11: 14522.874 | Y11: -10.973732 | Z11: 14511.9 | AS11: 49017.897 | AT11: -33.298489 | AU11: 48984.598 | AY11: 14340.328 | AZ11: -3.790424 | BA11: 14336.537
B12: 19年 | C12: 45492.168 | D12: -86.182166 | E12: 45405.986 | F12: 15585.213 | G12: -4.617952 | H12: 15580.595 | I12: 8891.1732 | J12: -26.87921 | K12: 8864.294 | L12: 2538.3366 | M12: -12.298141 | N12: 2526.0385 | O12: 8480.7624 | P12: -13.677903 | Q12: 8467.0845 | R12: 13659.803 | S12: -9.957358 | T12: 13649.846 | U12: 11922.093 | V12: -23.369554 | W12: 11898.723 | X12: 15585.213 | Y12: -4.617952 | Z12: 15580.595 | AS12: 61077.382 | AT12: -90.800118 | AU12: 60986.582 | AY12: 11922.093 | AZ12: -23.369554 | BA12: 11898.723
B13: 增长率 | C13: -0.24173712 | E13: -0.24078958 | F13: -0.068163279 | H13: -0.068591411 | I13: -0.58275129 | K13: -0.58238686 | L13: -0.74904433 | N13: -0.74814494 | O13: -0.25787752 | Q13: -0.25710492 | R13: -0.30349728 | T13: -0.30343799 | U13: 0.20283643 | W13: 0.20488029 | X13: -0.068163279 | Z13: -0.068591411 | AS13: -0.197446 | AU13: -0.19679712 | AY13: 0.20283643 | BA13: 0.20488029
B14: 20年毛利率 | C14: 0.3344916 | D14: -0.00045512121 | E14: 0.22652722 | F14: 0.33683365 | G14: -0.00057757113 | H14: 0.23362709 | I14: 0.34555164 | J14: -0.00090016161 | K14: 0.18880762 | L14: 0.20005655 | M14: -0.0011741473 | N14: 0.16406297 | O14: 0.31744599 | P14: -0.00040996453 | Q14: 0.21970903 | R14: 0.3303756 | S14: -0.00046238697 | T14: 0.22612926 | U14: 0.35336187 | V14: -0.00021738775 | W14: 0.24710162 | X14: 0.33683365 | Y14: -0.00057757113 | Z14: 0.23362709 | AS14: 0.3351821 | AT14: -0.00048930858 | AU14: 0.22858519 | AY14: 0.35336187 | AZ14: -0.00021738775 | BA14: 0.24710162
B15: 19年毛利率 | C15: 0.31100382 | D15: -0.0015639612 | E15: 0.22547379 | F15: 0.32586207 | G15: -0.00023900926 | H15: 0.23203066 | I15: 0.30631311 | J15: -0.002816117 | K15: 0.2298164 | L15: 0.26802446 | M15: -0.0036415295 | N15: 0.19661357 | O15: 0.30315963 | P15: -0.0010889978 | Q15: 0.20888505 | R15: 0.36002843 | S15: -0.00075710593 | T15: 0.26715807 | U15: 0.28478944 | V15: -0.0014188189 | W15: 0.2039759 | X15: 0.32586207 | Y15: -0.00023900926 | Z15: 0.23203066 | AS15: 0.31466494 | AT15: -0.0012200008 | AU15: 0.22711341 | AY15: 0.28478944 | AZ15: -0.0014188189 | BA15: 0.2039759
B16: 增减变动 | C16: 0.023487787 | D16: 0.00110884 | E16: 0.0010534248 | F16: 0.010971572 | G16: -0.00033856188 | H16: 0.0015964282 | I16: 0.039238524 | J16: 0.0019159554 | K16: -0.041008781 | L16: -0.067967915 | M16: 0.0024673823 | N16: -0.032550608 | O16: 0.014286361 | P16: 0.00067903328 | Q16: 0.010823984 | R16: -0.029652826 | S16: 0.00029471897 | T16: -0.041028809 | U16: 0.068572428 | V16: 0.0012014311 | W16: 0.043125718 | X16: 0.010971572 | Y16: -0.00033856188 | Z16: 0.0015964282 | AS16: 0.020517151 | AT16: 0.00073069217 | AU16: 0.0014717783 | AY16: 0.068572428 | AZ16: 0.0012014311 | BA16: 0.043125718
A17: 费用 | B17: 20年 | C17: 15556.633 | D17: -1335.0851 | E17: 14221.548 | F17: 6709.5636 | G17: -892.86136 | H17: 5816.7023 | I17: 2124.71 | J17: -163.27326 | K17: 1961.4367 | L17: 1024.3392 | M17: 36.328836 | N17: 1060.668 | O17: 2283.4293 | P17: -168.1423 | Q17: 2115.287 | R17: 4313.5904 | S17: -273.20516 | T17: 4040.3852 | U17: 5810.5645 | V17: -766.7932 | W17: 5043.7713 | X17: 6709.5636 | Y17: -892.86136 | Z17: 5816.7023 | AS17: 22266.197 | AT17: -2227.9465 | AU17: 20038.25 | AY17: 5810.5645 | AZ17: -766.7932 | BA17: 5043.7713
B18: 19年 | C18: 23353.356 | D18: -1021.9324 | E18: 22331.424 | F18: 7559.4133 | G18: -805.79854 | H18: 6753.6147 | I18: 4153.13 | J18: -59.579936 | K18: 4093.55 | L18: 1873.9097 | M18: -5.858451 | N18: 1868.0513 | O18: 4665.327 | P18: -264.5325 | Q18: 4400.7945 | R18: 5987.3857 | S18: -249.16399 | T18: 5738.2218 | U18: 6673.604 | V18: -442.79757 | W18: 6230.8064 | X18: 7559.4133 | Y18: -805.79854 | Z18: 6753.6147 | AS18: 30912.77 | AT18: -1827.731 | AU18: 29085.039 | AY18: 6673.604 | AZ18: -442.79757 | BA18: 6230.8064
B19: 增长率 | C19: -0.33385878 | E19: -0.36315981 | F19: -0.11242269 | H19: -0.13872755 | I19: -0.48840755 | K19: -0.52084702 | L19: -0.45336793 | N19: -0.43220617 | O19: -0.51055321 | Q19: -0.51933974 | R19: -0.27955362 | T19: -0.295882 | U19: -0.12932135 | W19: -0.19051067 | X19: -0.11242269 | Z19: -0.13872755 | AS19: -0.27970877 | AU19: -0.31104611 | AY19: -0.12932135 | BA19: -0.19051067
B20: 20年费用率 | C20: 0.15084968 | D20: -0.027217566 | E20: 0.093452731 | F20: 0.15561705 | G20: -0.046993215 | H20: 0.093643092 | I20: 0.19790581 | J20: -0.01840637 | K20: 0.10004042 | L20: 0.32169945 | M20: 0.052376994 | N20: 0.27352648 | O20: 0.11517201 | P20: -0.019100075 | Q20: 0.073884925 | R20: 0.14978889 | S20: -0.02062114 | T20: 0.096093054 | U20: 0.14317887 | V20: -0.043976992 | W20: 0.08693341 | X20: 0.15561705 | Y20: -0.046993215 | Z20: 0.093643092 | AS20: 0.15225522 | AT20: -0.032738822 | AU20: 0.093507909 | AY20: 0.14317887 | AZ20: -0.043976992 | BA20: 0.08693341
B21: 19年费用率 | C21: 0.15965348 | D21: -0.018545167 | E21: 0.11089179 | F21: 0.15805533 | G21: -0.041705351 | H21: 0.10057675 | I21: 0.14308103 | J21: -0.0062421503 | K21: 0.10612971 | L21: 0.19786724 | M21: -0.0017347112 | N21: 0.1453993 | O21: 0.16677024 | P21: -0.021061366 | Q21: 0.10856868 | R21: 0.15780821 | S21: -0.018945139 | T21: 0.11230986 | U21: 0.15941597 | V21: -0.026883249 | W21: 0.10681267 | X21: 0.15805533 | Y21: -0.041705351 | Z21: 0.10057675 | AS21: 0.15925969 | AT21: -0.024557602 | AU21: 0.10831239 | AY21: 0.15941597 | AZ21: -0.026883249 | BA21: 0.10681267
B22: 增减变动 | C22: -0.0088037975 | D22: -0.0086723984 | E22: -0.017439055 | F22: -0.0024382851 | G22: -0.0052878638 | H22: -0.0069336602 | I22: 0.054824784 | J22: -0.01216422 | K22: -0.0060892883 | L22: 0.12383222 | M22: 0.054111705 | N22: 0.12812718 | O22: -0.051598236 | P22: 0.0019612907 | Q22: -0.034683753 | R22: -0.0080193168 | S22: -0.001676001 | T22: -0.016216802 | U22: -0.016237094 | V22: -0.017093743 | W22: -0.019879256 | X22: -0.0024382851 | Y22: -0.0052878638 | Z22: -0.0069336602 | AS22: -0.0070044734 | AT22: -0.0081812201 | AU22: -0.014804482 | AY22: -0.016237094 | AZ22: -0.017093743 | BA22: -0.019879256
A23: 利润 | B23: 20年 | C23: 18938.389 | D23: 1312.7603 | E23: 20251.15 | F23: 7813.3103 | G23: 881.88763 | H23: 8695.1979 | I23: 1585.1205 | J23: 155.2884 | K23: 1740.4089 | L23: -387.3292 | M23: -37.143228 | N23: -424.47243 | O23: 4010.3351 | P23: 164.53329 | Q23: 4174.8684 | R23: 5200.4999 | S23: 267.0791 | T23: 5467.579 | U23: 8529.7631 | V23: 763.00277 | W23: 9292.7659 | X23: 7813.3103 | Y23: 881.88763 | Z23: 8695.1979 | AS23: 26751.7 | AT23: 2194.648 | AU23: 28946.348 | AY23: 8529.7631 | AZ23: 763.00277 | BA23: 9292.7659 | BB23: -0.083994454
B24: 19年 | C24: 22138.812 | D24: 935.75028 | E24: 23074.562 | F24: 8025.7999 | G24: 801.18059 | H24: 8826.9805 | I24: 4738.0432 | J24: 32.700726 | K24: 4770.7439 | L24: 664.42687 | M24: -6.43969 | N24: 657.98718 | O24: 3815.4354 | P24: 250.8546 | Q24: 4066.29 | R24: 7672.4176 | S24: 239.20663 | T24: 7911.6243 | U24: 5248.4889 | V24: 419.42802 | W24: 5667.9169 | X24: 8025.7999 | Y24: 801.18059 | Z24: 8826.9805 | AS24: 30164.612 | AT24: 1736.9309 | AU24: 31901.543 | AY24: 5248.4889 | AZ24: 419.42802 | BA24: 5667.9169 | BB24: 0.52916394
B25: 增长率 | C25: -0.14456162 | D25: 0.40289601 | E25: -0.12236039 | F25: -0.02647582 | G25: 0.10073514 | H25: -0.014929521 | I25: -0.66544827 | J25: 3.7487754 | K25: -0.63519129 | L25: -1.5829523 | N25: -1.6451074 | O25: 0.051081907 | P25: -0.34410892 | Q25: 0.026702082 | R25: -0.32218238 | S25: 0.11652046 | T25: -0.30891827 | U25: 0.62518456 | V25: 0.8191507 | W25: 0.63953813 | X25: -0.02647582 | Y25: 0.10073514 | Z25: -0.014929521 | AS25: -0.11314292 | AT25: 0.26352061 | AU25: -0.092634865 | AV25: 0.0041 | AW25: -0.096734865 | AY25: 0.62518456 | AZ25: 0.8191507 | BA25: 0.63953813
B26: 20年利润率 | C26: 0.18364192 | D26: 0.026762445 | E26: 0.13307449 | F26: 0.1812166 | G26: 0.046415644 | H26: 0.13998399 | I26: 0.14764583 | J26: 0.017506208 | K26: 0.088767201 | L26: -0.12164291 | M26: -0.053551141 | N26: -0.10946352 | O26: 0.20227398 | P26: 0.01869011 | Q26: 0.14582411 | R26: 0.18058671 | S26: 0.020158753 | T26: 0.13003621 | U26: 0.210183 | V26: 0.043759604 | W26: 0.16016821 | X26: 0.1812166 | Y26: 0.046415644 | Z26: 0.13998399 | AS26: 0.18292688 | AT26: 0.032249514 | AU26: 0.13507728 | AY26: 0.210183 | AZ26: 0.043759604 | BA26: 0.16016821
B27: 19年利润率 | C27: 0.15135034 | D27: 0.016981206 | E27: 0.11458201 | F27: 0.16780674 | G27: 0.041466342 | H27: 0.13145391 | I27: 0.16323209 | J27: 0.0034260333 | K27: 0.12368669 | L27: 0.070157226 | M27: -0.0019068184 | N27: 0.051214268 | O27: 0.13638939 | P27: 0.019972368 | Q27: 0.10031637 | R27: 0.20222022 | S27: 0.018188033 | T27: 0.15484821 | U27: 0.12537348 | V27: 0.02546443 | W27: 0.097163236 | X27: 0.16780674 | Y27: 0.041466342 | Z27: 0.13145391 | AS27: 0.15540525 | AT27: 0.023337601 | AU27: 0.11880102 | AY27: 0.12537348 | AZ27: 0.02546443 | BA27: 0.097163236
B28: 增减变动 | C28: 0.032291584 | D28: 0.0097812384 | E28: 0.01849248 | F28: 0.013409858 | G28: 0.0049493019 | H28: 0.0085300884 | I28: -0.015586259 | J28: 0.014080175 | K28: -0.034919493 | L28: -0.19180013 | M28: -0.051644323 | N28: -0.16067779 | O28: 0.065884597 | P28: -0.0012822574 | Q28: 0.045507737 | R28: -0.021633509 | S28: 0.0019707199 | T28: -0.024812007 | U28: 0.084809522 | V28: 0.018295174 | W28: 0.063004974 | X28: 0.013409858 | Y28: 0.0049493019 | Z28: 0.0085300884 | AS28: 0.027521624 | AT28: 0.0089119122 | AU28: 0.01627626 | AY28: 0.084809522 | AZ28: 0.018295174 | BA28: 0.063004974
A29: 核对： | C29: 5.0931703e-11 | D29: 5.0022209e-12 | E29: 3.2741809e-11 | F29: 0 | G29: 1.4779289e-12 | H29: 0 | I29: 0 | J29: 6.5369932e-13 | K29: 2.7284841e-12 | L29: 9.6633812e-13 | M29: 0 | N29: 1.1368684e-12 | O29: -2.1373125e-11 | P29: -4.5474735e-13 | Q29: -2.0008883e-11 | R29: 4.9112714e-11 | S29: 0 | T29: 5.4569682e-11 | AS29: 4.3655746e-11 | AT29: -7.730705e-12 | AU29: 2.910383e-11
C30: -4.3655746e-11 | D30: -6.1390892e-12 | E30: -3.6379788e-11 | F30: 7.2759576e-12 | G30: 0 | H30: 0 | I30: -4.8203219e-11 | J30: 8.4554586e-13 | K30: -4.7293724e-11 | L30: 5.0022209e-12 | M30: 2.3980817e-13 | N30: 4.888534e-12 | O30: 2.0918378e-11 | P30: 0 | Q30: 2.1373125e-11 | R30: 0 | S30: 3.4106051e-13 | T30: 0 | AS30: -2.910383e-11 | AT30: 0 | AU30: 0
S33: 1.4753231

Sheet 基数汇总
F1: 0 | AP1: 橱柜营销线M/N值调整汇总表
A2: 表6.实际表=表1+表2+表3+表4+表5 | B2: 实际+剔除补贴+剔除增城+成本调整 | F2: 是 | G2: 是 | H2: 是 | I2: 是 | J2: 是 | K2: 是 | W2: 表5：基数实际表 | Z2: =F2 -> 是 | AA2: =G2 -> 是 | AB2: =H2 -> 是 | AC2: =I2 -> 是 | AD2: =J2 -> 是 | AE2: =K2 -> 是 | AF2: =L2 -> 0 | AG2: =M2 -> 0 | ... AK2: =Q2 -> 0 | CB2: =F2 -> 是 | CC2: =G2 -> 是 | CD2: =H2 -> 是 | CE2: =I2 -> 是 | CF2: =J2 -> 是 | CG2: =K2 -> 是 | CH2: =L2 -> 0 | CI2: =M2 -> 0 | ... CN2: =R2 -> 0
A3: 部门 | B3: 项目 | C3: 口径 | D3: 类别 | E3: 本月 | F3: 1月 | G3: 2月 | H3: 3月 | I3: 4月 | J3: 5月 | K3: 6月 | L3: 7月 | M3: 8月 | N3: 9月 | O3: 10月 | P3: 11月 | Q3: 12月 | R3: 本年累计 | S3: 同期 | V3: 基数 | W3: 2020年部门名称 | X3: 项目 | Y3: 本月 | Z3: 1月 | AA3: 2月 | AB3: 3月 | AC3: 4月 | AD3: 5月 | AE3: 6月 | AF3: 7月 | AG3: 8月 | AH3: 9月 | AI3: 10月 | AJ3: 11月 | AK3: 12月 | AL3: 本年累计 | AM3: 同期 | AP3: 表5.橱柜营销线M/N值调整汇总（基数）=表4+表3 | AS3: =Z2 -> 是 | AT3: =AA2 -> 是 | AU3: =AB2 -> 是 | AV3: =AC2 -> 是 | AW3: =AD2 -> 是 | AX3: =AE2 -> 是 | AY3: =AF2 -> 0 | AZ3: =AG2 -> 0 | ... BD3: =AK2 -> 0 | BH3: =F2 -> 是 | BI3: =G2 -> 是 | BJ3: =H2 -> 是 | BK3: =I2 -> 是 | BL3: =J2 -> 是 | BM3: =K2 -> 是 | BN3: =L2 -> 0 | BO3: =M2 -> 0 | ... BS3: =Q2 -> 0 | BZ3: 大礼包 | CA3: 本月 | CB3: 1月 | CC3: 2月 | CD3: 3月 | CE3: 4月 | CF3: 5月 | CG3: 6月 | CH3: 7月 | CI3: 8月 | CJ3: 9月 | CK3: 10月 | CL3: 11月 | CM3: 12月 | CN3: 本年累计 | CO3: 同期
A4: 橱柜经销一部 | B4: 收入 | C4: 按产品 | D4: 柜门 | E4: =K4 -> 3392.3086 | F4: 2271.0135 | G4: 683.0953 | H4: 1973.7591 | I4: 2692.0759 | J4: 2900.2694 | K4: 3392.3086 | L4: 3817.283 | M4: 3883.3402 | N4: 3556.811 | O4: 3047.548 | P4: 3351.1119 | Q4: 3428.5239 | R4: 34997.14 | S4: =SUMIFS(F4:Q4,$F$2:$Q$2,"是") -> 13912.522 | T4: 基数 | V4: 基数 | W4: 橱柜经销一部 | X4: 房租 | Y4: =AE4 -> 3.9773909 | Z4: 0.63301828 | AA4: 0.64290318 | AB4: 0.59290318 | AC4: -0.036409115 | AD4: 2.8952019 | AE4: 3.9773909 | AF4: 2.0979909 | AG4: 2.1479909 | AH4: 2.7269909 | AI4: 2.7269909 | AJ4: 3.3969909 | AK4: 3.3969909 | AL4: 25.198954 | AM4: =SUMIFS(Z4:AK4,$Z$2:$AK$2,"是") -> 8.7050083 | AP4: 序号 | AQ4: 部门 | AS4: M值指标情况 | BH4: N值指标情况 | BX4: TZ0091 | BY4: 橱柜经销一部 | BZ4: 收入 | CA4: =CG4 -> 0.275 | CB4: 24.91 | CC4: 6.325 | CD4: 10.56 | CE4: 10.055 | CF4: 4.16 | CG4: 0.275 | CH4: 14.415 | CI4: 15.13 | CJ4: 7.59 | CK4: 3.685 | CL4: 8.305 | CM4: 3.3 | CN4: 108.71 | CO4: =SUMIFS(CB4:CM4,$F$2:$Q$2,"是") -> 56.285
A5: 橱柜经销一部 | B5: 收入 | C5: 按产品 | D5: 台面 | E5: =K5 -> 2022.2313 | F5: 1165.9941 | G5: 425.8761 | H5: 972.194 | I5: 1563.8114 | J5: 1858.2594 | K5: 2022.2313 | L5: 1999.2671 | M5: 1914.8097 | N5: 1831.1195 | O5: 1688.0693 | P5: 1960.5722 | Q5: 2076.9125 | R5: 19479.117 | S5: =SUMIFS(F5:Q5,$F$2:$Q$2,"是") -> 8008.3663 | T5: 基数 | V5: 基数 | W5: 橱柜经销一部 | X5: 水费 | Y5: =AE5 -> 0.041796 | Z5: 0.119556 | AA5: 0.042768 | AB5: 0.03402 | AC5: 0.032562 | AD5: 0.037422 | AE5: 0.041796 | AF5: 0.044226 | AG5: 0.044226 | AH5: 0.082414 | AI5: 0.067554 | AJ5: 0.040338 | AK5: 0.073872 | AL5: 0.660754 | AM5: =SUMIFS(Z5:AK5,$Z$2:$AK$2,"是") -> 0.308124 | AR5: 本月 | AS5: 1月 | AT5: 2月 | AU5: 3月 | AV5: 4月 | AW5: 5月 | AX5: 6月 | AY5: 7月 | AZ5: 8月 | BA5: 9月 | BB5: 10月 | BC5: 11月 | BD5: 12月 | BE5: 本年M值累计 | BF5: 同期 | BG5: 本月 | BH5: 1月 | BI5: 2月 | BJ5: 3月 | BK5: 4月 | BL5: 5月 | BM5: 6月 | BN5: 7月 | BO5: 8月 | BP5: 9月 | BQ5: 10月 | BR5: 11月 | BS5: 12月 | BT5: 本年N值累计 | BU5: 同期 | BX5: TZ0092 | BY5: 橱柜经销二部 | BZ5: 收入 | CA5: =CG5 -> 3.04 | CB5: 25.175 | CC5: 19.435 | CD5: 11.02 | CE5: 16.75 | CF5: 7.615 | CG5: 3.04 | CH5: 14.635 | CI5: 12.575 | CJ5: 11.99 | CK5: 23.57 | CL5: 15.84 | CM5: 4.675 | CN5: 166.32 | CO5: =SUMIFS(CB5:CM5,$F$2:$Q$2,"是") -> 83.035
A6: 橱柜经销一部 | B6: 收入 | C6: 按产品 | D6: OEM烟灶 | E6: =K6 -> 1051.0142 | F6: 545.97619 | G6: 194.04775 | H6: 960.76985 | I6: 964.26035 | J6: 1056.834 | K6: 1051.0142 | L6: 685.12106 | M6: 387.98021 | N6: 477.51717 | O6: 616.4769 | P6: 687.78849 | Q6: 498.93431 | R6: 8126.7205 | S6: =SUMIFS(F6:Q6,$F$2:$Q$2,"是") -> 4772.9023 | T6: 基数 | V6: 基数 | W6: 橱柜经销一部 | X6: 电费 | Y6: =AE6 -> 0.19544 | Z6: 0.10048 | AA6: 0.0652 | AB6: 0.12048 | AC6: 0.15072 | AD6: 0.16264 | AE6: 0.19544 | AF6: 0.22856 | AG6: 0.25512 | AH6: 0.24897 | AI6: 0.240921 | AJ6: 0.19969 | AK6: 0.15447 | AL6: 2.122691 | AM6: =SUMIFS(Z6:AK6,$Z$2:$AK$2,"是") -> 0.79496 | AP6: 1 | AQ6: 橱柜经销一部 | AR6: =AX6 -> 0.057155 | AS6: 4.589966 | AT6: 1.268917 | AU6: 2.067512 | AV6: 1.796353 | AW6: 0.845133 | AX6: 0.057155 | AY6: 3.029382 | AZ6: 3.240785 | BA6: 1.653571 | BB6: 0.80526 | BC6: 1.807054 | BD6: 0.715303 | BE6: 21.876391 | BF6: =SUMIFS(AS6:BD6,$AS$3:$BD$3,"是") -> 10.625036 | BG6: =BM6 -> 0.275 | BH6: 24.91 | BI6: 6.325 | BJ6: 10.56 | BK6: 10.055 | BL6: 4.16 | BM6: 0.275 | BN6: 14.415 | BO6: 15.13 | BP6: 7.59 | BQ6: 3.685 | BR6: 8.305 | BS6: 3.3 | BT6: 108.71 | BU6: =SUMIFS(BH6:BS6,$BH$3:$BS$3,"是") -> 56.285 | BX6: TZ0093 | BY6: 橱柜经销三分部 | BZ6: 收入 | CA6: =CG6 -> 0.22 | CB6: 19.55 | CC6: 1.87 | CD6: 6.92 | CE6: 2.385 | CF6: 3.165 | CG6: 0.22 | CH6: 11.765 | CI6: 12.545 | CJ6: 8.03 | CK6: 7.425 | CL6: 5.404 | CM6: 8.47 | CN6: 87.749 | CO6: =SUMIFS(CB6:CM6,$F$2:$Q$2,"是") -> 34.11
A7: 橱柜经销一部 | B7: 收入 | C7: 按产品 | D7: OEM其他 | E7: =K7 -> 1518.0457 | F7: 669.10002 | G7: 216.24924 | H7: 850.9555 | I7: 1216.2173 | J7: 1377.5036 | K7: 1518.0457 | L7: 1090.8743 | M7: 1322.7164 | N7: 1421.8503 | O7: 1302.6485 | P7: 1262.7462 | Q7: 1393.8252 | R7: 13642.732 | S7: =SUMIFS(F7:Q7,$F$2:$Q$2,"是") -> 5848.0713 | T7: 基数 | V7: 基数 | W7: 橱柜经销一部 | X7: 办公费 | Y7: =AE7 -> 2.5168612 | Z7: 0.789478 | AA7: 0.483046 | AB7: 0.311864 | AC7: 6.5112765 | AD7: 0.259553 | AE7: 2.5168612 | AF7: 2.4070954 | AG7: 2.079791 | AH7: 2.213605 | AI7: 2.126552 | AJ7: 1.4730034 | AK7: 2.921029 | AL7: 24.093155 | AM7: =SUMIFS(Z7:AK7,$Z$2:$AK$2,"是") -> 10.872079 | AO7: TZ0091 | AP7: 2 | AQ7: 其中：剔除礼包 | AR7: =AX7 -> 0.057155 | AS7: 4.589966 | AT7: 1.268917 | AU7: 2.067512 | AV7: 1.796353 | AW7: 0.845133 | AX7: 0.057155 | AY7: 3.029382 | AZ7: 3.240785 | BA7: 1.653571 | BB7: 0.80526 | BC7: 1.807054 | BD7: 0.715303 | BE7: 21.876391 | BF7: =SUMIFS(AS7:BD7,$AS$3:$BD$3,"是") -> 10.625036 | BG7: =BM7 -> 0.275 | BH7: 24.91 | BI7: 6.325 | BJ7: 10.56 | BK7: 10.055 | BL7: 4.16 | BM7: 0.275 | BN7: 14.415 | BO7: 15.13 | BP7: 7.59 | BQ7: 3.685 | BR7: 8.305 | BS7: 3.3 | BT7: 108.71 | BU7: =SUMIFS(BH7:BS7,$BH$3:$BS$3,"是") -> 56.285 | BX7: TZ0094 | BY7: 橱柜经销四部 | BZ7: 收入 | CA7: =CG7 -> 0.055 | CB7: 13.09 | CC7: 6.16 | CD7: 7.9 | CE7: 2.585 | CF7: 1.33 | CG7: 0.055 | CH7: 6.795 | CI7: 6.215 | CJ7: 2.835 | CK7: 3.575 | CL7: 3.025 | CM7: 6.93 | CN7: 60.495 | CO7: =SUMIFS(CB7:CM7,$F$2:$Q$2,"是") -> 31.12
